Workbook
Name T_max: 'Założenia'!$B$2
Name A_max: 'Założenia'!$B$3
Name mu_r_24: 'Założenia'!$B$7
Name sig_r_24: 'Założenia'!$C$7
Name mu_r_5p: 'Założenia'!$B$8
Name sig_r_5p: 'Założenia'!$C$8
Name mu_m_13: 'Założenia'!$B$12
Name sig_m_13: 'Założenia'!$C$12
Name mu_m_45: 'Założenia'!$B$13
Name sig_m_45: 'Założenia'!$C$13
Name mu_m_6p: 'Założenia'!$B$14
Name sig_m_6p: 'Założenia'!$C$14
Name h_nat_tbl: 'Założenia'!$A$18:$B$27
Name res_zywe_t30: 'Wyniki'!$G$32
Name res_zgony_t30: 'Wyniki'!$I$32
Name res_peak: 'Wyniki'!$B$37
Name res_peak_t: 'Wyniki'!$B$38
Name res_urodz: 'Wyniki'!$B$39
Name res_wiek_t30: 'Wyniki'!$K$32
Name res_wymarcie: 'Wyniki'!$B$42

Sheet Założenia
A1: Parametr | B1: Wartość
A2: T_max (liczba kroków) | B2: 30
A3: A_max (kohorty wiekowe) | B3: 10
A5: Stopa urodzeń ~ Normal(μ, σ)
A6: Pasmo wieku | B6: μ | C6: σ
A7: 2–4 u.j.c. | B7: 0.15 | C7: 0.02
A8: 5+ u.j.c. | B8: 0.1 | C8: 0.01
A10: Śmiertelność choroby ~ Normal(μ, σ)
A11: Pasmo wieku | B11: μ | C11: σ
A12: 1–3 u.j.c. | B12: 0.2 | C12: 0.05
A13: 4–5 u.j.c. | B13: 0.3 | C13: 0.07
A14: 6+ u.j.c. | B14: 0.5 | C14: 0.15
A16: Naturalna śmiertelność (hazard z N(6, 1))
A17: wiek a | B17: h_nat(a)
A18: 1 | B18: 0
A19: 2 | B19: 3.1e-05
A20: 3 | B20: 0.001318
A21: 4 | B21: 0.021429
A22: 5 | B22: 0.139069
A23: 6 | B23: 0.405713
A24: 7 | B24: 0.682689
A25: 8 | B25: 0.856607
A26: 9 | B26: 0.940664
A27: 10 | B27: 1
A30: Stan początkowy (t=0)
A31: wiek a | B31: z | C31: o | D31: ca | E31: cb
A32: 1 | B32: 60 | C32: 20 | D32: 10 | E32: 10
A33: 2 | B33: 60 | C33: 30 | D33: 10 | E33: 20
A34: 3 | B34: 70 | C34: 10 | D34: 5 | E34: 10
A35: 4 | B35: 60 | C35: 10 | D35: 10 | E35: 5
A36: 5 | B36: 20 | C36: 20 | D36: 7 | E36: 3
A37: 6 | B37: 10 | C37: 5 | D37: 6 | E37: 4
A38: 7 | B38: 10 | C38: 0 | D38: 0 | E38: 3
A39: 8 | B39: 0 | C39: 0 | D39: 0 | E39: 0
A40: 9 | B40: 0 | C40: 0 | D40: 0 | E40: 0
A41: 10 | B41: 0 | C41: 0 | D41: 0 | E41: 0
A42: Σ | B42: =SUM(B32:B41) | C42: =SUM(C32:C41) | D42: =SUM(D32:D41) | E42: =SUM(E32:E41)
A43: Razem populacja | B43: =SUM(B32:E41)
A46: Kolejność operacji w kroku t → t+1
A47: 1. Wyznacz pch(t) = (Σ ca + Σ cb) / Σ żywych (stan początku kroku).
...

Sheet z
A1: t \ a | B1: a=1 | C1: a=2 | D1: a=3 | E1: a=4 | F1: a=5 | G1: a=6 | H1: a=7 | I1: a=8 | J1: a=9 | K1: a=10
A2: 0 | B2: ='Założenia'!B32 | C2: ='Założenia'!B33 | D2: ='Założenia'!B34 | E2: ='Założenia'!B35 | F2: ='Założenia'!B36 | G2: ='Założenia'!B37 | H2: ='Założenia'!B38 | I2: ='Założenia'!B39 | J2: ='Założenia'!B40 | K2: ='Założenia'!B41
A3: 1 | B3: =MAX(0,(SUM(urodz!C3:K3)-SUM(urodz_ch!C3:K3))-nat_z!B3) | C3: =MAX(0,(z!B2-pca!B3+o!B2)-nat_z!C3) | D3: =MAX(0,(z!C2-pca!C3+o!C2)-nat_z!D3) | E3: =MAX(0,(z!D2-pca!D3+o!D2)-nat_z!E3) | F3: =MAX(0,(z!E2-pca!E3+o!E2)-nat_z!F3) | G3: =MAX(0,(z!F2-pca!F3+o!F2)-nat_z!G3) | H3: =MAX(0,(z!G2-pca!G3+o!G2)-nat_z!H3) | I3: =MAX(0,(z!H2-pca!H3+o!H2)-nat_z!I3) | J3: =MAX(0,(z!I2-pca!I3+o!I2)-nat_z!J3) | K3: =MAX(0,(z!J2-pca!J3+o!J2)-nat_z!K3)
A4: 2 | B4: =MAX(0,(SUM(urodz!C4:K4)-SUM(urodz_ch!C4:K4))-nat_z!B4) | C4: =MAX(0,(z!B3-pca!B4+o!B3)-nat_z!C4) | D4: =MAX(0,(z!C3-pca!C4+o!C3)-nat_z!D4) | E4: =MAX(0,(z!D3-pca!D4+o!D3)-nat_z!E4) | F4: =MAX(0,(z!E3-pca!E4+o!E3)-nat_z!F4) | G4: =MAX(0,(z!F3-pca!F4+o!F3)-nat_z!G4) | H4: =MAX(0,(z!G3-pca!G4+o!G3)-nat_z!H4) | I4: =MAX(0,(z!H3-pca!H4+o!H3)-nat_z!I4) | J4: =MAX(0,(z!I3-pca!I4+o!I3)-nat_z!J4) | K4: =MAX(0,(z!J3-pca!J4+o!J3)-nat_z!K4)
A5: 3 | B5: =MAX(0,(SUM(urodz!C5:K5)-SUM(urodz_ch!C5:K5))-nat_z!B5) | C5: =MAX(0,(z!B4-pca!B5+o!B4)-nat_z!C5) | D5: =MAX(0,(z!C4-pca!C5+o!C4)-nat_z!D5) | E5: =MAX(0,(z!D4-pca!D5+o!D4)-nat_z!E5) | F5: =MAX(0,(z!E4-pca!E5+o!E4)-nat_z!F5) | G5: =MAX(0,(z!F4-pca!F5+o!F4)-nat_z!G5) | H5: =MAX(0,(z!G4-pca!G5+o!G4)-nat_z!H5) | I5: =MAX(0,(z!H4-pca!H5+o!H4)-nat_z!I5) | J5: =MAX(0,(z!I4-pca!I5+o!I4)-nat_z!J5) | K5: =MAX(0,(z!J4-pca!J5+o!J4)-nat_z!K5)
A6: 4 | B6: =MAX(0,(SUM(urodz!C6:K6)-SUM(urodz_ch!C6:K6))-nat_z!B6) | C6: =MAX(0,(z!B5-pca!B6+o!B5)-nat_z!C6) | D6: =MAX(0,(z!C5-pca!C6+o!C5)-nat_z!D6) | E6: =MAX(0,(z!D5-pca!D6+o!D5)-nat_z!E6) | F6: =MAX(0,(z!E5-pca!E6+o!E5)-nat_z!F6) | G6: =MAX(0,(z!F5-pca!F6+o!F5)-nat_z!G6) | H6: =MAX(0,(z!G5-pca!G6+o!G5)-nat_z!H6) | I6: =MAX(0,(z!H5-pca!H6+o!H5)-nat_z!I6) | J6: =MAX(0,(z!I5-pca!I6+o!I5)-nat_z!J6) | K6: =MAX(0,(z!J5-pca!J6+o!J5)-nat_z!K6)
A7: 5 | B7: =MAX(0,(SUM(urodz!C7:K7)-SUM(urodz_ch!C7:K7))-nat_z!B7) | C7: =MAX(0,(z!B6-pca!B7+o!B6)-nat_z!C7) | D7: =MAX(0,(z!C6-pca!C7+o!C6)-nat_z!D7) | E7: =MAX(0,(z!D6-pca!D7+o!D6)-nat_z!E7) | F7: =MAX(0,(z!E6-pca!E7+o!E6)-nat_z!F7) | G7: =MAX(0,(z!F6-pca!F7+o!F6)-nat_z!G7) | H7: =MAX(0,(z!G6-pca!G7+o!G6)-nat_z!H7) | I7: =MAX(0,(z!H6-pca!H7+o!H6)-nat_z!I7) | J7: =MAX(0,(z!I6-pca!I7+o!I6)-nat_z!J7) | K7: =MAX(0,(z!J6-pca!J7+o!J6)-nat_z!K7)
A8: 6 | B8: =MAX(0,(SUM(urodz!C8:K8)-SUM(urodz_ch!C8:K8))-nat_z!B8) | C8: =MAX(0,(z!B7-pca!B8+o!B7)-nat_z!C8) | D8: =MAX(0,(z!C7-pca!C8+o!C7)-nat_z!D8) | E8: =MAX(0,(z!D7-pca!D8+o!D7)-nat_z!E8) | F8: =MAX(0,(z!E7-pca!E8+o!E7)-nat_z!F8) | G8: =MAX(0,(z!F7-pca!F8+o!F7)-nat_z!G8) | H8: =MAX(0,(z!G7-pca!G8+o!G7)-nat_z!H8) | I8: =MAX(0,(z!H7-pca!H8+o!H7)-nat_z!I8) | J8: =MAX(0,(z!I7-pca!I8+o!I7)-nat_z!J8) | K8: =MAX(0,(z!J7-pca!J8+o!J7)-nat_z!K8)
A9: 7 | B9: =MAX(0,(SUM(urodz!C9:K9)-SUM(urodz_ch!C9:K9))-nat_z!B9) | C9: =MAX(0,(z!B8-pca!B9+o!B8)-nat_z!C9) | D9: =MAX(0,(z!C8-pca!C9+o!C8)-nat_z!D9) | E9: =MAX(0,(z!D8-pca!D9+o!D8)-nat_z!E9) | F9: =MAX(0,(z!E8-pca!E9+o!E8)-nat_z!F9) | G9: =MAX(0,(z!F8-pca!F9+o!F8)-nat_z!G9) | H9: =MAX(0,(z!G8-pca!G9+o!G8)-nat_z!H9) | I9: =MAX(0,(z!H8-pca!H9+o!H8)-nat_z!I9) | J9: =MAX(0,(z!I8-pca!I9+o!I8)-nat_z!J9) | K9: =MAX(0,(z!J8-pca!J9+o!J8)-nat_z!K9)
A10: 8 | B10: =MAX(0,(SUM(urodz!C10:K10)-SUM(urodz_ch!C10:K10))-nat_z!B10) | C10: =MAX(0,(z!B9-pca!B10+o!B9)-nat_z!C10) | D10: =MAX(0,(z!C9-pca!C10+o!C9)-nat_z!D10) | E10: =MAX(0,(z!D9-pca!D10+o!D9)-nat_z!E10) | F10: =MAX(0,(z!E9-pca!E10+o!E9)-nat_z!F10) | G10: =MAX(0,(z!F9-pca!F10+o!F9)-nat_z!G10) | H10: =MAX(0,(z!G9-pca!G10+o!G9)-nat_z!H10) | I10: =MAX(0,(z!H9-pca!H10+o!H9)-nat_z!I10) | J10: =MAX(0,(z!I9-pca!I10+o!I9)-nat_z!J10) | K10: =MAX(0,(z!J9-pca!J10+o!J9)-nat_z!K10)
A11: 9 | B11: =MAX(0,(SUM(urodz!C11:K11)-SUM(urodz_ch!C11:K11))-nat_z!B11) | C11: =MAX(0,(z!B10-pca!B11+o!B10)-nat_z!C11) | D11: =MAX(0,(z!C10-pca!C11+o!C10)-nat_z!D11) | E11: =MAX(0,(z!D10-pca!D11+o!D10)-nat_z!E11) | F11: =MAX(0,(z!E10-pca!E11+o!E10)-nat_z!F11) | G11: =MAX(0,(z!F10-pca!F11+o!F10)-nat_z!G11) | H11: =MAX(0,(z!G10-pca!G11+o!G10)-nat_z!H11) | I11: =MAX(0,(z!H10-pca!H11+o!H10)-nat_z!I11) | J11: =MAX(0,(z!I10-pca!I11+o!I10)-nat_z!J11) | K11: =MAX(0,(z!J10-pca!J11+o!J10)-nat_z!K11)
A12: 10 | B12: =MAX(0,(SUM(urodz!C12:K12)-SUM(urodz_ch!C12:K12))-nat_z!B12) | C12: =MAX(0,(z!B11-pca!B12+o!B11)-nat_z!C12) | D12: =MAX(0,(z!C11-pca!C12+o!C11)-nat_z!D12) | E12: =MAX(0,(z!D11-pca!D12+o!D11)-nat_z!E12) | F12: =MAX(0,(z!E11-pca!E12+o!E11)-nat_z!F12) | G12: =MAX(0,(z!F11-pca!F12+o!F11)-nat_z!G12) | H12: =MAX(0,(z!G11-pca!G12+o!G11)-nat_z!H12) | I12: =MAX(0,(z!H11-pca!H12+o!H11)-nat_z!I12) | J12: =MAX(0,(z!I11-pca!I12+o!I11)-nat_z!J12) | K12: =MAX(0,(z!J11-pca!J12+o!J11)-nat_z!K12)
A13: 11 | B13: =MAX(0,(SUM(urodz!C13:K13)-SUM(urodz_ch!C13:K13))-nat_z!B13) | C13: =MAX(0,(z!B12-pca!B13+o!B12)-nat_z!C13) | D13: =MAX(0,(z!C12-pca!C13+o!C12)-nat_z!D13) | E13: =MAX(0,(z!D12-pca!D13+o!D12)-nat_z!E13) | F13: =MAX(0,(z!E12-pca!E13+o!E12)-nat_z!F13) | G13: =MAX(0,(z!F12-pca!F13+o!F12)-nat_z!G13) | H13: =MAX(0,(z!G12-pca!G13+o!G12)-nat_z!H13) | I13: =MAX(0,(z!H12-pca!H13+o!H12)-nat_z!I13) | J13: =MAX(0,(z!I12-pca!I13+o!I12)-nat_z!J13) | K13: =MAX(0,(z!J12-pca!J13+o!J12)-nat_z!K13)
A14: 12 | B14: =MAX(0,(SUM(urodz!C14:K14)-SUM(urodz_ch!C14:K14))-nat_z!B14) | C14: =MAX(0,(z!B13-pca!B14+o!B13)-nat_z!C14) | D14: =MAX(0,(z!C13-pca!C14+o!C13)-nat_z!D14) | E14: =MAX(0,(z!D13-pca!D14+o!D13)-nat_z!E14) | F14: =MAX(0,(z!E13-pca!E14+o!E13)-nat_z!F14) | G14: =MAX(0,(z!F13-pca!F14+o!F13)-nat_z!G14) | H14: =MAX(0,(z!G13-pca!G14+o!G13)-nat_z!H14) | I14: =MAX(0,(z!H13-pca!H14+o!H13)-nat_z!I14) | J14: =MAX(0,(z!I13-pca!I14+o!I13)-nat_z!J14) | K14: =MAX(0,(z!J13-pca!J14+o!J13)-nat_z!K14)
... A32: 30 | B32: =MAX(0,(SUM(urodz!C32:K32)-SUM(urodz_ch!C32:K32))-nat_z!B32) | C32: =MAX(0,(z!B31-pca!B32+o!B31)-nat_z!C32) | D32: =MAX(0,(z!C31-pca!C32+o!C31)-nat_z!D32) | E32: =MAX(0,(z!D31-pca!D32+o!D31)-nat_z!E32) | F32: =MAX(0,(z!E31-pca!E32+o!E31)-nat_z!F32) | G32: =MAX(0,(z!F31-pca!F32+o!F31)-nat_z!G32) | H32: =MAX(0,(z!G31-pca!G32+o!G31)-nat_z!H32) | I32: =MAX(0,(z!H31-pca!H32+o!H31)-nat_z!I32) | J32: =MAX(0,(z!I31-pca!I32+o!I31)-nat_z!J32) | K32: =MAX(0,(z!J31-pca!J32+o!J31)-nat_z!K32)

Sheet o
A1: t \ a | B1: a=1 | C1: a=2 | D1: a=3 | E1: a=4 | F1: a=5 | G1: a=6 | H1: a=7 | I1: a=8 | J1: a=9 | K1: a=10
A2: 0 | B2: ='Założenia'!C32 | C2: ='Założenia'!C33 | D2: ='Założenia'!C34 | E2: ='Założenia'!C35 | F2: ='Założenia'!C36 | G2: ='Założenia'!C37 | H2: ='Założenia'!C38 | I2: ='Założenia'!C39 | J2: ='Założenia'!C40 | K2: ='Założenia'!C41
A3: 1 | B3: =MAX(0,0-nat_o!B3) | C3: =MAX(0,(cb!B2-pu!B3)-nat_o!C3) | D3: =MAX(0,(cb!C2-pu!C3)-nat_o!D3) | E3: =MAX(0,(cb!D2-pu!D3)-nat_o!E3) | F3: =MAX(0,(cb!E2-pu!E3)-nat_o!F3) | G3: =MAX(0,(cb!F2-pu!F3)-nat_o!G3) | H3: =MAX(0,(cb!G2-pu!G3)-nat_o!H3) | I3: =MAX(0,(cb!H2-pu!H3)-nat_o!I3) | J3: =MAX(0,(cb!I2-pu!I3)-nat_o!J3) | K3: =MAX(0,(cb!J2-pu!J3)-nat_o!K3)
A4: 2 | B4: =MAX(0,0-nat_o!B4) | C4: =MAX(0,(cb!B3-pu!B4)-nat_o!C4) | D4: =MAX(0,(cb!C3-pu!C4)-nat_o!D4) | E4: =MAX(0,(cb!D3-pu!D4)-nat_o!E4) | F4: =MAX(0,(cb!E3-pu!E4)-nat_o!F4) | G4: =MAX(0,(cb!F3-pu!F4)-nat_o!G4) | H4: =MAX(0,(cb!G3-pu!G4)-nat_o!H4) | I4: =MAX(0,(cb!H3-pu!H4)-nat_o!I4) | J4: =MAX(0,(cb!I3-pu!I4)-nat_o!J4) | K4: =MAX(0,(cb!J3-pu!J4)-nat_o!K4)
A5: 3 | B5: =MAX(0,0-nat_o!B5) | C5: =MAX(0,(cb!B4-pu!B5)-nat_o!C5) | D5: =MAX(0,(cb!C4-pu!C5)-nat_o!D5) | E5: =MAX(0,(cb!D4-pu!D5)-nat_o!E5) | F5: =MAX(0,(cb!E4-pu!E5)-nat_o!F5) | G5: =MAX(0,(cb!F4-pu!F5)-nat_o!G5) | H5: =MAX(0,(cb!G4-pu!G5)-nat_o!H5) | I5: =MAX(0,(cb!H4-pu!H5)-nat_o!I5) | J5: =MAX(0,(cb!I4-pu!I5)-nat_o!J5) | K5: =MAX(0,(cb!J4-pu!J5)-nat_o!K5)
A6: 4 | B6: =MAX(0,0-nat_o!B6) | C6: =MAX(0,(cb!B5-pu!B6)-nat_o!C6) | D6: =MAX(0,(cb!C5-pu!C6)-nat_o!D6) | E6: =MAX(0,(cb!D5-pu!D6)-nat_o!E6) | F6: =MAX(0,(cb!E5-pu!E6)-nat_o!F6) | G6: =MAX(0,(cb!F5-pu!F6)-nat_o!G6) | H6: =MAX(0,(cb!G5-pu!G6)-nat_o!H6) | I6: =MAX(0,(cb!H5-pu!H6)-nat_o!I6) | J6: =MAX(0,(cb!I5-pu!I6)-nat_o!J6) | K6: =MAX(0,(cb!J5-pu!J6)-nat_o!K6)
A7: 5 | B7: =MAX(0,0-nat_o!B7) | C7: =MAX(0,(cb!B6-pu!B7)-nat_o!C7) | D7: =MAX(0,(cb!C6-pu!C7)-nat_o!D7) | E7: =MAX(0,(cb!D6-pu!D7)-nat_o!E7) | F7: =MAX(0,(cb!E6-pu!E7)-nat_o!F7) | G7: =MAX(0,(cb!F6-pu!F7)-nat_o!G7) | H7: =MAX(0,(cb!G6-pu!G7)-nat_o!H7) | I7: =MAX(0,(cb!H6-pu!H7)-nat_o!I7) | J7: =MAX(0,(cb!I6-pu!I7)-nat_o!J7) | K7: =MAX(0,(cb!J6-pu!J7)-nat_o!K7)
A8: 6 | B8: =MAX(0,0-nat_o!B8) | C8: =MAX(0,(cb!B7-pu!B8)-nat_o!C8) | D8: =MAX(0,(cb!C7-pu!C8)-nat_o!D8) | E8: =MAX(0,(cb!D7-pu!D8)-nat_o!E8) | F8: =MAX(0,(cb!E7-pu!E8)-nat_o!F8) | G8: =MAX(0,(cb!F7-pu!F8)-nat_o!G8) | H8: =MAX(0,(cb!G7-pu!G8)-nat_o!H8) | I8: =MAX(0,(cb!H7-pu!H8)-nat_o!I8) | J8: =MAX(0,(cb!I7-pu!I8)-nat_o!J8) | K8: =MAX(0,(cb!J7-pu!J8)-nat_o!K8)
A9: 7 | B9: =MAX(0,0-nat_o!B9) | C9: =MAX(0,(cb!B8-pu!B9)-nat_o!C9) | D9: =MAX(0,(cb!C8-pu!C9)-nat_o!D9) | E9: =MAX(0,(cb!D8-pu!D9)-nat_o!E9) | F9: =MAX(0,(cb!E8-pu!E9)-nat_o!F9) | G9: =MAX(0,(cb!F8-pu!F9)-nat_o!G9) | H9: =MAX(0,(cb!G8-pu!G9)-nat_o!H9) | I9: =MAX(0,(cb!H8-pu!H9)-nat_o!I9) | J9: =MAX(0,(cb!I8-pu!I9)-nat_o!J9) | K9: =MAX(0,(cb!J8-pu!J9)-nat_o!K9)
A10: 8 | B10: =MAX(0,0-nat_o!B10) | C10: =MAX(0,(cb!B9-pu!B10)-nat_o!C10) | D10: =MAX(0,(cb!C9-pu!C10)-nat_o!D10) | E10: =MAX(0,(cb!D9-pu!D10)-nat_o!E10) | F10: =MAX(0,(cb!E9-pu!E10)-nat_o!F10) | G10: =MAX(0,(cb!F9-pu!F10)-nat_o!G10) | H10: =MAX(0,(cb!G9-pu!G10)-nat_o!H10) | I10: =MAX(0,(cb!H9-pu!H10)-nat_o!I10) | J10: =MAX(0,(cb!I9-pu!I10)-nat_o!J10) | K10: =MAX(0,(cb!J9-pu!J10)-nat_o!K10)
A11: 9 | B11: =MAX(0,0-nat_o!B11) | C11: =MAX(0,(cb!B10-pu!B11)-nat_o!C11) | D11: =MAX(0,(cb!C10-pu!C11)-nat_o!D11) | E11: =MAX(0,(cb!D10-pu!D11)-nat_o!E11) | F11: =MAX(0,(cb!E10-pu!E11)-nat_o!F11) | G11: =MAX(0,(cb!F10-pu!F11)-nat_o!G11) | H11: =MAX(0,(cb!G10-pu!G11)-nat_o!H11) | I11: =MAX(0,(cb!H10-pu!H11)-nat_o!I11) | J11: =MAX(0,(cb!I10-pu!I11)-nat_o!J11) | K11: =MAX(0,(cb!J10-pu!J11)-nat_o!K11)
A12: 10 | B12: =MAX(0,0-nat_o!B12) | C12: =MAX(0,(cb!B11-pu!B12)-nat_o!C12) | D12: =MAX(0,(cb!C11-pu!C12)-nat_o!D12) | E12: =MAX(0,(cb!D11-pu!D12)-nat_o!E12) | F12: =MAX(0,(cb!E11-pu!E12)-nat_o!F12) | G12: =MAX(0,(cb!F11-pu!F12)-nat_o!G12) | H12: =MAX(0,(cb!G11-pu!G12)-nat_o!H12) | I12: =MAX(0,(cb!H11-pu!H12)-nat_o!I12) | J12: =MAX(0,(cb!I11-pu!I12)-nat_o!J12) | K12: =MAX(0,(cb!J11-pu!J12)-nat_o!K12)
A13: 11 | B13: =MAX(0,0-nat_o!B13) | C13: =MAX(0,(cb!B12-pu!B13)-nat_o!C13) | D13: =MAX(0,(cb!C12-pu!C13)-nat_o!D13) | E13: =MAX(0,(cb!D12-pu!D13)-nat_o!E13) | F13: =MAX(0,(cb!E12-pu!E13)-nat_o!F13) | G13: =MAX(0,(cb!F12-pu!F13)-nat_o!G13) | H13: =MAX(0,(cb!G12-pu!G13)-nat_o!H13) | I13: =MAX(0,(cb!H12-pu!H13)-nat_o!I13) | J13: =MAX(0,(cb!I12-pu!I13)-nat_o!J13) | K13: =MAX(0,(cb!J12-pu!J13)-nat_o!K13)
A14: 12 | B14: =MAX(0,0-nat_o!B14) | C14: =MAX(0,(cb!B13-pu!B14)-nat_o!C14) | D14: =MAX(0,(cb!C13-pu!C14)-nat_o!D14) | E14: =MAX(0,(cb!D13-pu!D14)-nat_o!E14) | F14: =MAX(0,(cb!E13-pu!E14)-nat_o!F14) | G14: =MAX(0,(cb!F13-pu!F14)-nat_o!G14) | H14: =MAX(0,(cb!G13-pu!G14)-nat_o!H14) | I14: =MAX(0,(cb!H13-pu!H14)-nat_o!I14) | J14: =MAX(0,(cb!I13-pu!I14)-nat_o!J14) | K14: =MAX(0,(cb!J13-pu!J14)-nat_o!K14)
... A32: 30 | B32: =MAX(0,0-nat_o!B32) | C32: =MAX(0,(cb!B31-pu!B32)-nat_o!C32) | D32: =MAX(0,(cb!C31-pu!C32)-nat_o!D32) | E32: =MAX(0,(cb!D31-pu!D32)-nat_o!E32) | F32: =MAX(0,(cb!E31-pu!E32)-nat_o!F32) | G32: =MAX(0,(cb!F31-pu!F32)-nat_o!G32) | H32: =MAX(0,(cb!G31-pu!G32)-nat_o!H32) | I32: =MAX(0,(cb!H31-pu!H32)-nat_o!I32) | J32: =MAX(0,(cb!I31-pu!I32)-nat_o!J32) | K32: =MAX(0,(cb!J31-pu!J32)-nat_o!K32)

Sheet ca
A1: t \ a | B1: a=1 | C1: a=2 | D1: a=3 | E1: a=4 | F1: a=5 | G1: a=6 | H1: a=7 | I1: a=8 | J1: a=9 | K1: a=10
A2: 0 | B2: ='Założenia'!D32 | C2: ='Założenia'!D33 | D2: ='Założenia'!D34 | E2: ='Założenia'!D35 | F2: ='Założenia'!D36 | G2: ='Założenia'!D37 | H2: ='Założenia'!D38 | I2: ='Założenia'!D39 | J2: ='Założenia'!D40 | K2: ='Założenia'!D41
A3: 1 | B3: =MAX(0,SUM(urodz_ch!C3:K3)-nat_ca!B3) | C3: =MAX(0,pca!B3-nat_ca!C3) | D3: =MAX(0,pca!C3-nat_ca!D3) | E3: =MAX(0,pca!D3-nat_ca!E3) | F3: =MAX(0,pca!E3-nat_ca!F3) | G3: =MAX(0,pca!F3-nat_ca!G3) | H3: =MAX(0,pca!G3-nat_ca!H3) | I3: =MAX(0,pca!H3-nat_ca!I3) | J3: =MAX(0,pca!I3-nat_ca!J3) | K3: =MAX(0,pca!J3-nat_ca!K3)
A4: 2 | B4: =MAX(0,SUM(urodz_ch!C4:K4)-nat_ca!B4) | C4: =MAX(0,pca!B4-nat_ca!C4) | D4: =MAX(0,pca!C4-nat_ca!D4) | E4: =MAX(0,pca!D4-nat_ca!E4) | F4: =MAX(0,pca!E4-nat_ca!F4) | G4: =MAX(0,pca!F4-nat_ca!G4) | H4: =MAX(0,pca!G4-nat_ca!H4) | I4: =MAX(0,pca!H4-nat_ca!I4) | J4: =MAX(0,pca!I4-nat_ca!J4) | K4: =MAX(0,pca!J4-nat_ca!K4)
A5: 3 | B5: =MAX(0,SUM(urodz_ch!C5:K5)-nat_ca!B5) | C5: =MAX(0,pca!B5-nat_ca!C5) | D5: =MAX(0,pca!C5-nat_ca!D5) | E5: =MAX(0,pca!D5-nat_ca!E5) | F5: =MAX(0,pca!E5-nat_ca!F5) | G5: =MAX(0,pca!F5-nat_ca!G5) | H5: =MAX(0,pca!G5-nat_ca!H5) | I5: =MAX(0,pca!H5-nat_ca!I5) | J5: =MAX(0,pca!I5-nat_ca!J5) | K5: =MAX(0,pca!J5-nat_ca!K5)
A6: 4 | B6: =MAX(0,SUM(urodz_ch!C6:K6)-nat_ca!B6) | C6: =MAX(0,pca!B6-nat_ca!C6) | D6: =MAX(0,pca!C6-nat_ca!D6) | E6: =MAX(0,pca!D6-nat_ca!E6) | F6: =MAX(0,pca!E6-nat_ca!F6) | G6: =MAX(0,pca!F6-nat_ca!G6) | H6: =MAX(0,pca!G6-nat_ca!H6) | I6: =MAX(0,pca!H6-nat_ca!I6) | J6: =MAX(0,pca!I6-nat_ca!J6) | K6: =MAX(0,pca!J6-nat_ca!K6)
A7: 5 | B7: =MAX(0,SUM(urodz_ch!C7:K7)-nat_ca!B7) | C7: =MAX(0,pca!B7-nat_ca!C7) | D7: =MAX(0,pca!C7-nat_ca!D7) | E7: =MAX(0,pca!D7-nat_ca!E7) | F7: =MAX(0,pca!E7-nat_ca!F7) | G7: =MAX(0,pca!F7-nat_ca!G7) | H7: =MAX(0,pca!G7-nat_ca!H7) | I7: =MAX(0,pca!H7-nat_ca!I7) | J7: =MAX(0,pca!I7-nat_ca!J7) | K7: =MAX(0,pca!J7-nat_ca!K7)
A8: 6 | B8: =MAX(0,SUM(urodz_ch!C8:K8)-nat_ca!B8) | C8: =MAX(0,pca!B8-nat_ca!C8) | D8: =MAX(0,pca!C8-nat_ca!D8) | E8: =MAX(0,pca!D8-nat_ca!E8) | F8: =MAX(0,pca!E8-nat_ca!F8) | G8: =MAX(0,pca!F8-nat_ca!G8) | H8: =MAX(0,pca!G8-nat_ca!H8) | I8: =MAX(0,pca!H8-nat_ca!I8) | J8: =MAX(0,pca!I8-nat_ca!J8) | K8: =MAX(0,pca!J8-nat_ca!K8)
A9: 7 | B9: =MAX(0,SUM(urodz_ch!C9:K9)-nat_ca!B9) | C9: =MAX(0,pca!B9-nat_ca!C9) | D9: =MAX(0,pca!C9-nat_ca!D9) | E9: =MAX(0,pca!D9-nat_ca!E9) | F9: =MAX(0,pca!E9-nat_ca!F9) | G9: =MAX(0,pca!F9-nat_ca!G9) | H9: =MAX(0,pca!G9-nat_ca!H9) | I9: =MAX(0,pca!H9-nat_ca!I9) | J9: =MAX(0,pca!I9-nat_ca!J9) | K9: =MAX(0,pca!J9-nat_ca!K9)
A10: 8 | B10: =MAX(0,SUM(urodz_ch!C10:K10)-nat_ca!B10) | C10: =MAX(0,pca!B10-nat_ca!C10) | D10: =MAX(0,pca!C10-nat_ca!D10) | E10: =MAX(0,pca!D10-nat_ca!E10) | F10: =MAX(0,pca!E10-nat_ca!F10) | G10: =MAX(0,pca!F10-nat_ca!G10) | H10: =MAX(0,pca!G10-nat_ca!H10) | I10: =MAX(0,pca!H10-nat_ca!I10) | J10: =MAX(0,pca!I10-nat_ca!J10) | K10: =MAX(0,pca!J10-nat_ca!K10)
A11: 9 | B11: =MAX(0,SUM(urodz_ch!C11:K11)-nat_ca!B11) | C11: =MAX(0,pca!B11-nat_ca!C11) | D11: =MAX(0,pca!C11-nat_ca!D11) | E11: =MAX(0,pca!D11-nat_ca!E11) | F11: =MAX(0,pca!E11-nat_ca!F11) | G11: =MAX(0,pca!F11-nat_ca!G11) | H11: =MAX(0,pca!G11-nat_ca!H11) | I11: =MAX(0,pca!H11-nat_ca!I11) | J11: =MAX(0,pca!I11-nat_ca!J11) | K11: =MAX(0,pca!J11-nat_ca!K11)
A12: 10 | B12: =MAX(0,SUM(urodz_ch!C12:K12)-nat_ca!B12) | C12: =MAX(0,pca!B12-nat_ca!C12) | D12: =MAX(0,pca!C12-nat_ca!D12) | E12: =MAX(0,pca!D12-nat_ca!E12) | F12: =MAX(0,pca!E12-nat_ca!F12) | G12: =MAX(0,pca!F12-nat_ca!G12) | H12: =MAX(0,pca!G12-nat_ca!H12) | I12: =MAX(0,pca!H12-nat_ca!I12) | J12: =MAX(0,pca!I12-nat_ca!J12) | K12: =MAX(0,pca!J12-nat_ca!K12)
A13: 11 | B13: =MAX(0,SUM(urodz_ch!C13:K13)-nat_ca!B13) | C13: =MAX(0,pca!B13-nat_ca!C13) | D13: =MAX(0,pca!C13-nat_ca!D13) | E13: =MAX(0,pca!D13-nat_ca!E13) | F13: =MAX(0,pca!E13-nat_ca!F13) | G13: =MAX(0,pca!F13-nat_ca!G13) | H13: =MAX(0,pca!G13-nat_ca!H13) | I13: =MAX(0,pca!H13-nat_ca!I13) | J13: =MAX(0,pca!I13-nat_ca!J13) | K13: =MAX(0,pca!J13-nat_ca!K13)
A14: 12 | B14: =MAX(0,SUM(urodz_ch!C14:K14)-nat_ca!B14) | C14: =MAX(0,pca!B14-nat_ca!C14) | D14: =MAX(0,pca!C14-nat_ca!D14) | E14: =MAX(0,pca!D14-nat_ca!E14) | F14: =MAX(0,pca!E14-nat_ca!F14) | G14: =MAX(0,pca!F14-nat_ca!G14) | H14: =MAX(0,pca!G14-nat_ca!H14) | I14: =MAX(0,pca!H14-nat_ca!I14) | J14: =MAX(0,pca!I14-nat_ca!J14) | K14: =MAX(0,pca!J14-nat_ca!K14)
... A32: 30 | B32: =MAX(0,SUM(urodz_ch!C32:K32)-nat_ca!B32) | C32: =MAX(0,pca!B32-nat_ca!C32) | D32: =MAX(0,pca!C32-nat_ca!D32) | E32: =MAX(0,pca!D32-nat_ca!E32) | F32: =MAX(0,pca!E32-nat_ca!F32) | G32: =MAX(0,pca!F32-nat_ca!G32) | H32: =MAX(0,pca!G32-nat_ca!H32) | I32: =MAX(0,pca!H32-nat_ca!I32) | J32: =MAX(0,pca!I32-nat_ca!J32) | K32: =MAX(0,pca!J32-nat_ca!K32)

Sheet cb
A1: t \ a | B1: a=1 | C1: a=2 | D1: a=3 | E1: a=4 | F1: a=5 | G1: a=6 | H1: a=7 | I1: a=8 | J1: a=9 | K1: a=10
A2: 0 | B2: ='Założenia'!E32 | C2: ='Założenia'!E33 | D2: ='Założenia'!E34 | E2: ='Założenia'!E35 | F2: ='Założenia'!E36 | G2: ='Założenia'!E37 | H2: ='Założenia'!E38 | I2: ='Założenia'!E39 | J2: ='Założenia'!E40 | K2: ='Założenia'!E41
A3: 1 | B3: =MAX(0,0-nat_cb!B3) | C3: =MAX(0,ca!B2-nat_cb!C3) | D3: =MAX(0,ca!C2-nat_cb!D3) | E3: =MAX(0,ca!D2-nat_cb!E3) | F3: =MAX(0,ca!E2-nat_cb!F3) | G3: =MAX(0,ca!F2-nat_cb!G3) | H3: =MAX(0,ca!G2-nat_cb!H3) | I3: =MAX(0,ca!H2-nat_cb!I3) | J3: =MAX(0,ca!I2-nat_cb!J3) | K3: =MAX(0,ca!J2-nat_cb!K3)
A4: 2 | B4: =MAX(0,0-nat_cb!B4) | C4: =MAX(0,ca!B3-nat_cb!C4) | D4: =MAX(0,ca!C3-nat_cb!D4) | E4: =MAX(0,ca!D3-nat_cb!E4) | F4: =MAX(0,ca!E3-nat_cb!F4) | G4: =MAX(0,ca!F3-nat_cb!G4) | H4: =MAX(0,ca!G3-nat_cb!H4) | I4: =MAX(0,ca!H3-nat_cb!I4) | J4: =MAX(0,ca!I3-nat_cb!J4) | K4: =MAX(0,ca!J3-nat_cb!K4)
A5: 3 | B5: =MAX(0,0-nat_cb!B5) | C5: =MAX(0,ca!B4-nat_cb!C5) | D5: =MAX(0,ca!C4-nat_cb!D5) | E5: =MAX(0,ca!D4-nat_cb!E5) | F5: =MAX(0,ca!E4-nat_cb!F5) | G5: =MAX(0,ca!F4-nat_cb!G5) | H5: =MAX(0,ca!G4-nat_cb!H5) | I5: =MAX(0,ca!H4-nat_cb!I5) | J5: =MAX(0,ca!I4-nat_cb!J5) | K5: =MAX(0,ca!J4-nat_cb!K5)
A6: 4 | B6: =MAX(0,0-nat_cb!B6) | C6: =MAX(0,ca!B5-nat_cb!C6) | D6: =MAX(0,ca!C5-nat_cb!D6) | E6: =MAX(0,ca!D5-nat_cb!E6) | F6: =MAX(0,ca!E5-nat_cb!F6) | G6: =MAX(0,ca!F5-nat_cb!G6) | H6: =MAX(0,ca!G5-nat_cb!H6) | I6: =MAX(0,ca!H5-nat_cb!I6) | J6: =MAX(0,ca!I5-nat_cb!J6) | K6: =MAX(0,ca!J5-nat_cb!K6)
A7: 5 | B7: =MAX(0,0-nat_cb!B7) | C7: =MAX(0,ca!B6-nat_cb!C7) | D7: =MAX(0,ca!C6-nat_cb!D7) | E7: =MAX(0,ca!D6-nat_cb!E7) | F7: =MAX(0,ca!E6-nat_cb!F7) | G7: =MAX(0,ca!F6-nat_cb!G7) | H7: =MAX(0,ca!G6-nat_cb!H7) | I7: =MAX(0,ca!H6-nat_cb!I7) | J7: =MAX(0,ca!I6-nat_cb!J7) | K7: =MAX(0,ca!J6-nat_cb!K7)
A8: 6 | B8: =MAX(0,0-nat_cb!B8) | C8: =MAX(0,ca!B7-nat_cb!C8) | D8: =MAX(0,ca!C7-nat_cb!D8) | E8: =MAX(0,ca!D7-nat_cb!E8) | F8: =MAX(0,ca!E7-nat_cb!F8) | G8: =MAX(0,ca!F7-nat_cb!G8) | H8: =MAX(0,ca!G7-nat_cb!H8) | I8: =MAX(0,ca!H7-nat_cb!I8) | J8: =MAX(0,ca!I7-nat_cb!J8) | K8: =MAX(0,ca!J7-nat_cb!K8)
A9: 7 | B9: =MAX(0,0-nat_cb!B9) | C9: =MAX(0,ca!B8-nat_cb!C9) | D9: =MAX(0,ca!C8-nat_cb!D9) | E9: =MAX(0,ca!D8-nat_cb!E9) | F9: =MAX(0,ca!E8-nat_cb!F9) | G9: =MAX(0,ca!F8-nat_cb!G9) | H9: =MAX(0,ca!G8-nat_cb!H9) | I9: =MAX(0,ca!H8-nat_cb!I9) | J9: =MAX(0,ca!I8-nat_cb!J9) | K9: =MAX(0,ca!J8-nat_cb!K9)
A10: 8 | B10: =MAX(0,0-nat_cb!B10) | C10: =MAX(0,ca!B9-nat_cb!C10) | D10: =MAX(0,ca!C9-nat_cb!D10) | E10: =MAX(0,ca!D9-nat_cb!E10) | F10: =MAX(0,ca!E9-nat_cb!F10) | G10: =MAX(0,ca!F9-nat_cb!G10) | H10: =MAX(0,ca!G9-nat_cb!H10) | I10: =MAX(0,ca!H9-nat_cb!I10) | J10: =MAX(0,ca!I9-nat_cb!J10) | K10: =MAX(0,ca!J9-nat_cb!K10)
A11: 9 | B11: =MAX(0,0-nat_cb!B11) | C11: =MAX(0,ca!B10-nat_cb!C11) | D11: =MAX(0,ca!C10-nat_cb!D11) | E11: =MAX(0,ca!D10-nat_cb!E11) | F11: =MAX(0,ca!E10-nat_cb!F11) | G11: =MAX(0,ca!F10-nat_cb!G11) | H11: =MAX(0,ca!G10-nat_cb!H11) | I11: =MAX(0,ca!H10-nat_cb!I11) | J11: =MAX(0,ca!I10-nat_cb!J11) | K11: =MAX(0,ca!J10-nat_cb!K11)
A12: 10 | B12: =MAX(0,0-nat_cb!B12) | C12: =MAX(0,ca!B11-nat_cb!C12) | D12: =MAX(0,ca!C11-nat_cb!D12) | E12: =MAX(0,ca!D11-nat_cb!E12) | F12: =MAX(0,ca!E11-nat_cb!F12) | G12: =MAX(0,ca!F11-nat_cb!G12) | H12: =MAX(0,ca!G11-nat_cb!H12) | I12: =MAX(0,ca!H11-nat_cb!I12) | J12: =MAX(0,ca!I11-nat_cb!J12) | K12: =MAX(0,ca!J11-nat_cb!K12)
A13: 11 | B13: =MAX(0,0-nat_cb!B13) | C13: =MAX(0,ca!B12-nat_cb!C13) | D13: =MAX(0,ca!C12-nat_cb!D13) | E13: =MAX(0,ca!D12-nat_cb!E13) | F13: =MAX(0,ca!E12-nat_cb!F13) | G13: =MAX(0,ca!F12-nat_cb!G13) | H13: =MAX(0,ca!G12-nat_cb!H13) | I13: =MAX(0,ca!H12-nat_cb!I13) | J13: =MAX(0,ca!I12-nat_cb!J13) | K13: =MAX(0,ca!J12-nat_cb!K13)
A14: 12 | B14: =MAX(0,0-nat_cb!B14) | C14: =MAX(0,ca!B13-nat_cb!C14) | D14: =MAX(0,ca!C13-nat_cb!D14) | E14: =MAX(0,ca!D13-nat_cb!E14) | F14: =MAX(0,ca!E13-nat_cb!F14) | G14: =MAX(0,ca!F13-nat_cb!G14) | H14: =MAX(0,ca!G13-nat_cb!H14) | I14: =MAX(0,ca!H13-nat_cb!I14) | J14: =MAX(0,ca!I13-nat_cb!J14) | K14: =MAX(0,ca!J13-nat_cb!K14)
... A32: 30 | B32: =MAX(0,0-nat_cb!B32) | C32: =MAX(0,ca!B31-nat_cb!C32) | D32: =MAX(0,ca!C31-nat_cb!D32) | E32: =MAX(0,ca!D31-nat_cb!E32) | F32: =MAX(0,ca!E31-nat_cb!F32) | G32: =MAX(0,ca!F31-nat_cb!G32) | H32: =MAX(0,ca!G31-nat_cb!H32) | I32: =MAX(0,ca!H31-nat_cb!I32) | J32: =MAX(0,ca!I31-nat_cb!J32) | K32: =MAX(0,ca!J31-nat_cb!K32)

Sheet pch
A1: t | B1: pch(t)
A2: 0 | B2: =IFERROR((SUM(ca!B2:K2)+SUM(cb!B2:K2))/(SUM(z!B2:K2)+SUM(o!B2:K2)+SUM(ca!B2:K2)+SUM(cb!B2:K2)),0)
A3: 1 | B3: =IFERROR((SUM(ca!B3:K3)+SUM(cb!B3:K3))/(SUM(z!B3:K3)+SUM(o!B3:K3)+SUM(ca!B3:K3)+SUM(cb!B3:K3)),0)
A4: 2 | B4: =IFERROR((SUM(ca!B4:K4)+SUM(cb!B4:K4))/(SUM(z!B4:K4)+SUM(o!B4:K4)+SUM(ca!B4:K4)+SUM(cb!B4:K4)),0)
A5: 3 | B5: =IFERROR((SUM(ca!B5:K5)+SUM(cb!B5:K5))/(SUM(z!B5:K5)+SUM(o!B5:K5)+SUM(ca!B5:K5)+SUM(cb!B5:K5)),0)
A6: 4 | B6: =IFERROR((SUM(ca!B6:K6)+SUM(cb!B6:K6))/(SUM(z!B6:K6)+SUM(o!B6:K6)+SUM(ca!B6:K6)+SUM(cb!B6:K6)),0)
A7: 5 | B7: =IFERROR((SUM(ca!B7:K7)+SUM(cb!B7:K7))/(SUM(z!B7:K7)+SUM(o!B7:K7)+SUM(ca!B7:K7)+SUM(cb!B7:K7)),0)
A8: 6 | B8: =IFERROR((SUM(ca!B8:K8)+SUM(cb!B8:K8))/(SUM(z!B8:K8)+SUM(o!B8:K8)+SUM(ca!B8:K8)+SUM(cb!B8:K8)),0)
A9: 7 | B9: =IFERROR((SUM(ca!B9:K9)+SUM(cb!B9:K9))/(SUM(z!B9:K9)+SUM(o!B9:K9)+SUM(ca!B9:K9)+SUM(cb!B9:K9)),0)
A10: 8 | B10: =IFERROR((SUM(ca!B10:K10)+SUM(cb!B10:K10))/(SUM(z!B10:K10)+SUM(o!B10:K10)+SUM(ca!B10:K10)+SUM(cb!B10:K10)),0)
A11: 9 | B11: =IFERROR((SUM(ca!B11:K11)+SUM(cb!B11:K11))/(SUM(z!B11:K11)+SUM(o!B11:K11)+SUM(ca!B11:K11)+SUM(cb!B11:K11)),0)
A12: 10 | B12: =IFERROR((SUM(ca!B12:K12)+SUM(cb!B12:K12))/(SUM(z!B12:K12)+SUM(o!B12:K12)+SUM(ca!B12:K12)+SUM(cb!B12:K12)),0)
A13: 11 | B13: =IFERROR((SUM(ca!B13:K13)+SUM(cb!B13:K13))/(SUM(z!B13:K13)+SUM(o!B13:K13)+SUM(ca!B13:K13)+SUM(cb!B13:K13)),0)
... A32: 30 | B32: =IFERROR((SUM(ca!B32:K32)+SUM(cb!B32:K32))/(SUM(z!B32:K32)+SUM(o!B32:K32)+SUM(ca!B32:K32)+SUM(cb!B32:K32)),0)

Sheet r_st
A1: t \ a | B1: a=1 | C1: a=2 | D1: a=3 | E1: a=4 | F1: a=5 | G1: a=6 | H1: a=7 | I1: a=8 | J1: a=9 | K1: a=10
A2: 0 | B2: =0 | C2: =MAX(0,MIN(1,_xlfn.NORM.INV(RAND(),mu_r_24,sig_r_24))) | D2: =MAX(0,MIN(1,_xlfn.NORM.INV(RAND(),mu_r_24,sig_r_24))) | E2: =MAX(0,MIN(1,_xlfn.NORM.INV(RAND(),mu_r_24,sig_r_24))) | F2: =MAX(0,MIN(1,_xlfn.NORM.INV(RAND(),mu_r_5p,sig_r_5p))) | G2: =MAX(0,MIN(1,_xlfn.NORM.INV(RAND(),mu_r_5p,sig_r_5p))) | H2: =MAX(0,MIN(1,_xlfn.NORM.INV(RAND(),mu_r_5p,sig_r_5p))) | I2: =MAX(0,MIN(1,_xlfn.NORM.INV(RAND(),mu_r_5p,sig_r_5p))) | J2: =MAX(0,MIN(1,_xlfn.NORM.INV(RAND(),mu_r_5p,sig_r_5p))) | K2: =MAX(0,MIN(1,_xlfn.NORM.INV(RAND(),mu_r_5p,sig_r_5p)))
A3: 1 | B3: =0 | C3: =MAX(0,MIN(1,_xlfn.NORM.INV(RAND(),mu_r_24,sig_r_24))) | D3: =MAX(0,MIN(1,_xlfn.NORM.INV(RAND(),mu_r_24,sig_r_24))) | E3: =MAX(0,MIN(1,_xlfn.NORM.INV(RAND(),mu_r_24,sig_r_24))) | F3: =MAX(0,MIN(1,_xlfn.NORM.INV(RAND(),mu_r_5p,sig_r_5p))) | G3: =MAX(0,MIN(1,_xlfn.NORM.INV(RAND(),mu_r_5p,sig_r_5p))) | H3: =MAX(0,MIN(1,_xlfn.NORM.INV(RAND(),mu_r_5p,sig_r_5p))) | I3: =MAX(0,MIN(1,_xlfn.NORM.INV(RAND(),mu_r_5p,sig_r_5p))) | J3: =MAX(0,MIN(1,_xlfn.NORM.INV(RAND(),mu_r_5p,sig_r_5p))) | K3: =MAX(0,MIN(1,_xlfn.NORM.INV(RAND(),mu_r_5p,sig_r_5p)))
A4: 2 | B4: =0 | C4: =MAX(0,MIN(1,_xlfn.NORM.INV(RAND(),mu_r_24,sig_r_24))) | D4: =MAX(0,MIN(1,_xlfn.NORM.INV(RAND(),mu_r_24,sig_r_24))) | E4: =MAX(0,MIN(1,_xlfn.NORM.INV(RAND(),mu_r_24,sig_r_24))) | F4: =MAX(0,MIN(1,_xlfn.NORM.INV(RAND(),mu_r_5p,sig_r_5p))) | G4: =MAX(0,MIN(1,_xlfn.NORM.INV(RAND(),mu_r_5p,sig_r_5p))) | H4: =MAX(0,MIN(1,_xlfn.NORM.INV(RAND(),mu_r_5p,sig_r_5p))) | I4: =MAX(0,MIN(1,_xlfn.NORM.INV(RAND(),mu_r_5p,sig_r_5p))) | J4: =MAX(0,MIN(1,_xlfn.NORM.INV(RAND(),mu_r_5p,sig_r_5p))) | K4: =MAX(0,MIN(1,_xlfn.NORM.INV(RAND(),mu_r_5p,sig_r_5p)))
A5: 3 | B5: =0 | C5: =MAX(0,MIN(1,_xlfn.NORM.INV(RAND(),mu_r_24,sig_r_24))) | D5: =MAX(0,MIN(1,_xlfn.NORM.INV(RAND(),mu_r_24,sig_r_24))) | E5: =MAX(0,MIN(1,_xlfn.NORM.INV(RAND(),mu_r_24,sig_r_24))) | F5: =MAX(0,MIN(1,_xlfn.NORM.INV(RAND(),mu_r_5p,sig_r_5p))) | G5: =MAX(0,MIN(1,_xlfn.NORM.INV(RAND(),mu_r_5p,sig_r_5p))) | H5: =MAX(0,MIN(1,_xlfn.NORM.INV(RAND(),mu_r_5p,sig_r_5p))) | I5: =MAX(0,MIN(1,_xlfn.NORM.INV(RAND(),mu_r_5p,sig_r_5p))) | J5: =MAX(0,MIN(1,_xlfn.NORM.INV(RAND(),mu_r_5p,sig_r_5p))) | K5: =MAX(0,MIN(1,_xlfn.NORM.INV(RAND(),mu_r_5p,sig_r_5p)))
A6: 4 | B6: =0 | C6: =MAX(0,MIN(1,_xlfn.NORM.INV(RAND(),mu_r_24,sig_r_24))) | D6: =MAX(0,MIN(1,_xlfn.NORM.INV(RAND(),mu_r_24,sig_r_24))) | E6: =MAX(0,MIN(1,_xlfn.NORM.INV(RAND(),mu_r_24,sig_r_24))) | F6: =MAX(0,MIN(1,_xlfn.NORM.INV(RAND(),mu_r_5p,sig_r_5p))) | G6: =MAX(0,MIN(1,_xlfn.NORM.INV(RAND(),mu_r_5p,sig_r_5p))) | H6: =MAX(0,MIN(1,_xlfn.NORM.INV(RAND(),mu_r_5p,sig_r_5p))) | I6: =MAX(0,MIN(1,_xlfn.NORM.INV(RAND(),mu_r_5p,sig_r_5p))) | J6: =MAX(0,MIN(1,_xlfn.NORM.INV(RAND(),mu_r_5p,sig_r_5p))) | K6: =MAX(0,MIN(1,_xlfn.NORM.INV(RAND(),mu_r_5p,sig_r_5p)))
A7: 5 | B7: =0 | C7: =MAX(0,MIN(1,_xlfn.NORM.INV(RAND(),mu_r_24,sig_r_24))) | D7: =MAX(0,MIN(1,_xlfn.NORM.INV(RAND(),mu_r_24,sig_r_24))) | E7: =MAX(0,MIN(1,_xlfn.NORM.INV(RAND(),mu_r_24,sig_r_24))) | F7: =MAX(0,MIN(1,_xlfn.NORM.INV(RAND(),mu_r_5p,sig_r_5p))) | G7: =MAX(0,MIN(1,_xlfn.NORM.INV(RAND(),mu_r_5p,sig_r_5p))) | H7: =MAX(0,MIN(1,_xlfn.NORM.INV(RAND(),mu_r_5p,sig_r_5p))) | I7: =MAX(0,MIN(1,_xlfn.NORM.INV(RAND(),mu_r_5p,sig_r_5p))) | J7: =MAX(0,MIN(1,_xlfn.NORM.INV(RAND(),mu_r_5p,sig_r_5p))) | K7: =MAX(0,MIN(1,_xlfn.NORM.INV(RAND(),mu_r_5p,sig_r_5p)))
A8: 6 | B8: =0 | C8: =MAX(0,MIN(1,_xlfn.NORM.INV(RAND(),mu_r_24,sig_r_24))) | D8: =MAX(0,MIN(1,_xlfn.NORM.INV(RAND(),mu_r_24,sig_r_24))) | E8: =MAX(0,MIN(1,_xlfn.NORM.INV(RAND(),mu_r_24,sig_r_24))) | F8: =MAX(0,MIN(1,_xlfn.NORM.INV(RAND(),mu_r_5p,sig_r_5p))) | G8: =MAX(0,MIN(1,_xlfn.NORM.INV(RAND(),mu_r_5p,sig_r_5p))) | H8: =MAX(0,MIN(1,_xlfn.NORM.INV(RAND(),mu_r_5p,sig_r_5p))) | I8: =MAX(0,MIN(1,_xlfn.NORM.INV(RAND(),mu_r_5p,sig_r_5p))) | J8: =MAX(0,MIN(1,_xlfn.NORM.INV(RAND(),mu_r_5p,sig_r_5p))) | K8: =MAX(0,MIN(1,_xlfn.NORM.INV(RAND(),mu_r_5p,sig_r_5p)))
A9: 7 | B9: =0 | C9: =MAX(0,MIN(1,_xlfn.NORM.INV(RAND(),mu_r_24,sig_r_24))) | D9: =MAX(0,MIN(1,_xlfn.NORM.INV(RAND(),mu_r_24,sig_r_24))) | E9: =MAX(0,MIN(1,_xlfn.NORM.INV(RAND(),mu_r_24,sig_r_24))) | F9: =MAX(0,MIN(1,_xlfn.NORM.INV(RAND(),mu_r_5p,sig_r_5p))) | G9: =MAX(0,MIN(1,_xlfn.NORM.INV(RAND(),mu_r_5p,sig_r_5p))) | H9: =MAX(0,MIN(1,_xlfn.NORM.INV(RAND(),mu_r_5p,sig_r_5p))) | I9: =MAX(0,MIN(1,_xlfn.NORM.INV(RAND(),mu_r_5p,sig_r_5p))) | J9: =MAX(0,MIN(1,_xlfn.NORM.INV(RAND(),mu_r_5p,sig_r_5p))) | K9: =MAX(0,MIN(1,_xlfn.NORM.INV(RAND(),mu_r_5p,sig_r_5p)))
A10: 8 | B10: =0 | C10: =MAX(0,MIN(1,_xlfn.NORM.INV(RAND(),mu_r_24,sig_r_24))) | D10: =MAX(0,MIN(1,_xlfn.NORM.INV(RAND(),mu_r_24,sig_r_24))) | E10: =MAX(0,MIN(1,_xlfn.NORM.INV(RAND(),mu_r_24,sig_r_24))) | F10: =MAX(0,MIN(1,_xlfn.NORM.INV(RAND(),mu_r_5p,sig_r_5p))) | G10: =MAX(0,MIN(1,_xlfn.NORM.INV(RAND(),mu_r_5p,sig_r_5p))) | H10: =MAX(0,MIN(1,_xlfn.NORM.INV(RAND(),mu_r_5p,sig_r_5p))) | I10: =MAX(0,MIN(1,_xlfn.NORM.INV(RAND(),mu_r_5p,sig_r_5p))) | J10: =MAX(0,MIN(1,_xlfn.NORM.INV(RAND(),mu_r_5p,sig_r_5p))) | K10: =MAX(0,MIN(1,_xlfn.NORM.INV(RAND(),mu_r_5p,sig_r_5p)))
A11: 9 | B11: =0 | C11: =MAX(0,MIN(1,_xlfn.NORM.INV(RAND(),mu_r_24,sig_r_24))) | D11: =MAX(0,MIN(1,_xlfn.NORM.INV(RAND(),mu_r_24,sig_r_24))) | E11: =MAX(0,MIN(1,_xlfn.NORM.INV(RAND(),mu_r_24,sig_r_24))) | F11: =MAX(0,MIN(1,_xlfn.NORM.INV(RAND(),mu_r_5p,sig_r_5p))) | G11: =MAX(0,MIN(1,_xlfn.NORM.INV(RAND(),mu_r_5p,sig_r_5p))) | H11: =MAX(0,MIN(1,_xlfn.NORM.INV(RAND(),mu_r_5p,sig_r_5p))) | I11: =MAX(0,MIN(1,_xlfn.NORM.INV(RAND(),mu_r_5p,sig_r_5p))) | J11: =MAX(0,MIN(1,_xlfn.NORM.INV(RAND(),mu_r_5p,sig_r_5p))) | K11: =MAX(0,MIN(1,_xlfn.NORM.INV(RAND(),mu_r_5p,sig_r_5p)))
A12: 10 | B12: =0 | C12: =MAX(0,MIN(1,_xlfn.NORM.INV(RAND(),mu_r_24,sig_r_24))) | D12: =MAX(0,MIN(1,_xlfn.NORM.INV(RAND(),mu_r_24,sig_r_24))) | E12: =MAX(0,MIN(1,_xlfn.NORM.INV(RAND(),mu_r_24,sig_r_24))) | F12: =MAX(0,MIN(1,_xlfn.NORM.INV(RAND(),mu_r_5p,sig_r_5p))) | G12: =MAX(0,MIN(1,_xlfn.NORM.INV(RAND(),mu_r_5p,sig_r_5p))) | H12: =MAX(0,MIN(1,_xlfn.NORM.INV(RAND(),mu_r_5p,sig_r_5p))) | I12: =MAX(0,MIN(1,_xlfn.NORM.INV(RAND(),mu_r_5p,sig_r_5p))) | J12: =MAX(0,MIN(1,_xlfn.NORM.INV(RAND(),mu_r_5p,sig_r_5p))) | K12: =MAX(0,MIN(1,_xlfn.NORM.INV(RAND(),mu_r_5p,sig_r_5p)))
A13: 11 | B13: =0 | C13: =MAX(0,MIN(1,_xlfn.NORM.INV(RAND(),mu_r_24,sig_r_24))) | D13: =MAX(0,MIN(1,_xlfn.NORM.INV(RAND(),mu_r_24,sig_r_24))) | E13: =MAX(0,MIN(1,_xlfn.NORM.INV(RAND(),mu_r_24,sig_r_24))) | F13: =MAX(0,MIN(1,_xlfn.NORM.INV(RAND(),mu_r_5p,sig_r_5p))) | G13: =MAX(0,MIN(1,_xlfn.NORM.INV(RAND(),mu_r_5p,sig_r_5p))) | H13: =MAX(0,MIN(1,_xlfn.NORM.INV(RAND(),mu_r_5p,sig_r_5p))) | I13: =MAX(0,MIN(1,_xlfn.NORM.INV(RAND(),mu_r_5p,sig_r_5p))) | J13: =MAX(0,MIN(1,_xlfn.NORM.INV(RAND(),mu_r_5p,sig_r_5p))) | K13: =MAX(0,MIN(1,_xlfn.NORM.INV(RAND(),mu_r_5p,sig_r_5p)))
... A32: 30 | B32: =0 | C32: =MAX(0,MIN(1,_xlfn.NORM.INV(RAND(),mu_r_24,sig_r_24))) | D32: =MAX(0,MIN(1,_xlfn.NORM.INV(RAND(),mu_r_24,sig_r_24))) | E32: =MAX(0,MIN(1,_xlfn.NORM.INV(RAND(),mu_r_24,sig_r_24))) | F32: =MAX(0,MIN(1,_xlfn.NORM.INV(RAND(),mu_r_5p,sig_r_5p))) | G32: =MAX(0,MIN(1,_xlfn.NORM.INV(RAND(),mu_r_5p,sig_r_5p))) | H32: =MAX(0,MIN(1,_xlfn.NORM.INV(RAND(),mu_r_5p,sig_r_5p))) | I32: =MAX(0,MIN(1,_xlfn.NORM.INV(RAND(),mu_r_5p,sig_r_5p))) | J32: =MAX(0,MIN(1,_xlfn.NORM.INV(RAND(),mu_r_5p,sig_r_5p))) | K32: =MAX(0,MIN(1,_xlfn.NORM.INV(RAND(),mu_r_5p,sig_r_5p)))

Sheet m_st
A1: t \ a | B1: a=1 | C1: a=2 | D1: a=3 | E1: a=4 | F1: a=5 | G1: a=6 | H1: a=7 | I1: a=8 | J1: a=9 | K1: a=10
A2: 0 | B2: =MAX(0,MIN(1,_xlfn.NORM.INV(RAND(),mu_m_13,sig_m_13))) | C2: =MAX(0,MIN(1,_xlfn.NORM.INV(RAND(),mu_m_13,sig_m_13))) | D2: =MAX(0,MIN(1,_xlfn.NORM.INV(RAND(),mu_m_13,sig_m_13))) | E2: =MAX(0,MIN(1,_xlfn.NORM.INV(RAND(),mu_m_45,sig_m_45))) | F2: =MAX(0,MIN(1,_xlfn.NORM.INV(RAND(),mu_m_45,sig_m_45))) | G2: =MAX(0,MIN(1,_xlfn.NORM.INV(RAND(),mu_m_6p,sig_m_6p))) | H2: =MAX(0,MIN(1,_xlfn.NORM.INV(RAND(),mu_m_6p,sig_m_6p))) | I2: =MAX(0,MIN(1,_xlfn.NORM.INV(RAND(),mu_m_6p,sig_m_6p))) | J2: =MAX(0,MIN(1,_xlfn.NORM.INV(RAND(),mu_m_6p,sig_m_6p))) | K2: =MAX(0,MIN(1,_xlfn.NORM.INV(RAND(),mu_m_6p,sig_m_6p)))
A3: 1 | B3: =MAX(0,MIN(1,_xlfn.NORM.INV(RAND(),mu_m_13,sig_m_13))) | C3: =MAX(0,MIN(1,_xlfn.NORM.INV(RAND(),mu_m_13,sig_m_13))) | D3: =MAX(0,MIN(1,_xlfn.NORM.INV(RAND(),mu_m_13,sig_m_13))) | E3: =MAX(0,MIN(1,_xlfn.NORM.INV(RAND(),mu_m_45,sig_m_45))) | F3: =MAX(0,MIN(1,_xlfn.NORM.INV(RAND(),mu_m_45,sig_m_45))) | G3: =MAX(0,MIN(1,_xlfn.NORM.INV(RAND(),mu_m_6p,sig_m_6p))) | H3: =MAX(0,MIN(1,_xlfn.NORM.INV(RAND(),mu_m_6p,sig_m_6p))) | I3: =MAX(0,MIN(1,_xlfn.NORM.INV(RAND(),mu_m_6p,sig_m_6p))) | J3: =MAX(0,MIN(1,_xlfn.NORM.INV(RAND(),mu_m_6p,sig_m_6p))) | K3: =MAX(0,MIN(1,_xlfn.NORM.INV(RAND(),mu_m_6p,sig_m_6p)))
A4: 2 | B4: =MAX(0,MIN(1,_xlfn.NORM.INV(RAND(),mu_m_13,sig_m_13))) | C4: =MAX(0,MIN(1,_xlfn.NORM.INV(RAND(),mu_m_13,sig_m_13))) | D4: =MAX(0,MIN(1,_xlfn.NORM.INV(RAND(),mu_m_13,sig_m_13))) | E4: =MAX(0,MIN(1,_xlfn.NORM.INV(RAND(),mu_m_45,sig_m_45))) | F4: =MAX(0,MIN(1,_xlfn.NORM.INV(RAND(),mu_m_45,sig_m_45))) | G4: =MAX(0,MIN(1,_xlfn.NORM.INV(RAND(),mu_m_6p,sig_m_6p))) | H4: =MAX(0,MIN(1,_xlfn.NORM.INV(RAND(),mu_m_6p,sig_m_6p))) | I4: =MAX(0,MIN(1,_xlfn.NORM.INV(RAND(),mu_m_6p,sig_m_6p))) | J4: =MAX(0,MIN(1,_xlfn.NORM.INV(RAND(),mu_m_6p,sig_m_6p))) | K4: =MAX(0,MIN(1,_xlfn.NORM.INV(RAND(),mu_m_6p,sig_m_6p)))
A5: 3 | B5: =MAX(0,MIN(1,_xlfn.NORM.INV(RAND(),mu_m_13,sig_m_13))) | C5: =MAX(0,MIN(1,_xlfn.NORM.INV(RAND(),mu_m_13,sig_m_13))) | D5: =MAX(0,MIN(1,_xlfn.NORM.INV(RAND(),mu_m_13,sig_m_13))) | E5: =MAX(0,MIN(1,_xlfn.NORM.INV(RAND(),mu_m_45,sig_m_45))) | F5: =MAX(0,MIN(1,_xlfn.NORM.INV(RAND(),mu_m_45,sig_m_45))) | G5: =MAX(0,MIN(1,_xlfn.NORM.INV(RAND(),mu_m_6p,sig_m_6p))) | H5: =MAX(0,MIN(1,_xlfn.NORM.INV(RAND(),mu_m_6p,sig_m_6p))) | I5: =MAX(0,MIN(1,_xlfn.NORM.INV(RAND(),mu_m_6p,sig_m_6p))) | J5: =MAX(0,MIN(1,_xlfn.NORM.INV(RAND(),mu_m_6p,sig_m_6p))) | K5: =MAX(0,MIN(1,_xlfn.NORM.INV(RAND(),mu_m_6p,sig_m_6p)))
A6: 4 | B6: =MAX(0,MIN(1,_xlfn.NORM.INV(RAND(),mu_m_13,sig_m_13))) | C6: =MAX(0,MIN(1,_xlfn.NORM.INV(RAND(),mu_m_13,sig_m_13))) | D6: =MAX(0,MIN(1,_xlfn.NORM.INV(RAND(),mu_m_13,sig_m_13))) | E6: =MAX(0,MIN(1,_xlfn.NORM.INV(RAND(),mu_m_45,sig_m_45))) | F6: =MAX(0,MIN(1,_xlfn.NORM.INV(RAND(),mu_m_45,sig_m_45))) | G6: =MAX(0,MIN(1,_xlfn.NORM.INV(RAND(),mu_m_6p,sig_m_6p))) | H6: =MAX(0,MIN(1,_xlfn.NORM.INV(RAND(),mu_m_6p,sig_m_6p))) | I6: =MAX(0,MIN(1,_xlfn.NORM.INV(RAND(),mu_m_6p,sig_m_6p))) | J6: =MAX(0,MIN(1,_xlfn.NORM.INV(RAND(),mu_m_6p,sig_m_6p))) | K6: =MAX(0,MIN(1,_xlfn.NORM.INV(RAND(),mu_m_6p,sig_m_6p)))
A7: 5 | B7: =MAX(0,MIN(1,_xlfn.NORM.INV(RAND(),mu_m_13,sig_m_13))) | C7: =MAX(0,MIN(1,_xlfn.NORM.INV(RAND(),mu_m_13,sig_m_13))) | D7: =MAX(0,MIN(1,_xlfn.NORM.INV(RAND(),mu_m_13,sig_m_13))) | E7: =MAX(0,MIN(1,_xlfn.NORM.INV(RAND(),mu_m_45,sig_m_45))) | F7: =MAX(0,MIN(1,_xlfn.NORM.INV(RAND(),mu_m_45,sig_m_45))) | G7: =MAX(0,MIN(1,_xlfn.NORM.INV(RAND(),mu_m_6p,sig_m_6p))) | H7: =MAX(0,MIN(1,_xlfn.NORM.INV(RAND(),mu_m_6p,sig_m_6p))) | I7: =MAX(0,MIN(1,_xlfn.NORM.INV(RAND(),mu_m_6p,sig_m_6p))) | J7: =MAX(0,MIN(1,_xlfn.NORM.INV(RAND(),mu_m_6p,sig_m_6p))) | K7: =MAX(0,MIN(1,_xlfn.NORM.INV(RAND(),mu_m_6p,sig_m_6p)))
A8: 6 | B8: =MAX(0,MIN(1,_xlfn.NORM.INV(RAND(),mu_m_13,sig_m_13))) | C8: =MAX(0,MIN(1,_xlfn.NORM.INV(RAND(),mu_m_13,sig_m_13))) | D8: =MAX(0,MIN(1,_xlfn.NORM.INV(RAND(),mu_m_13,sig_m_13))) | E8: =MAX(0,MIN(1,_xlfn.NORM.INV(RAND(),mu_m_45,sig_m_45))) | F8: =MAX(0,MIN(1,_xlfn.NORM.INV(RAND(),mu_m_45,sig_m_45))) | G8: =MAX(0,MIN(1,_xlfn.NORM.INV(RAND(),mu_m_6p,sig_m_6p))) | H8: =MAX(0,MIN(1,_xlfn.NORM.INV(RAND(),mu_m_6p,sig_m_6p))) | I8: =MAX(0,MIN(1,_xlfn.NORM.INV(RAND(),mu_m_6p,sig_m_6p))) | J8: =MAX(0,MIN(1,_xlfn.NORM.INV(RAND(),mu_m_6p,sig_m_6p))) | K8: =MAX(0,MIN(1,_xlfn.NORM.INV(RAND(),mu_m_6p,sig_m_6p)))
A9: 7 | B9: =MAX(0,MIN(1,_xlfn.NORM.INV(RAND(),mu_m_13,sig_m_13))) | C9: =MAX(0,MIN(1,_xlfn.NORM.INV(RAND(),mu_m_13,sig_m_13))) | D9: =MAX(0,MIN(1,_xlfn.NORM.INV(RAND(),mu_m_13,sig_m_13))) | E9: =MAX(0,MIN(1,_xlfn.NORM.INV(RAND(),mu_m_45,sig_m_45))) | F9: =MAX(0,MIN(1,_xlfn.NORM.INV(RAND(),mu_m_45,sig_m_45))) | G9: =MAX(0,MIN(1,_xlfn.NORM.INV(RAND(),mu_m_6p,sig_m_6p))) | H9: =MAX(0,MIN(1,_xlfn.NORM.INV(RAND(),mu_m_6p,sig_m_6p))) | I9: =MAX(0,MIN(1,_xlfn.NORM.INV(RAND(),mu_m_6p,sig_m_6p))) | J9: =MAX(0,MIN(1,_xlfn.NORM.INV(RAND(),mu_m_6p,sig_m_6p))) | K9: =MAX(0,MIN(1,_xlfn.NORM.INV(RAND(),mu_m_6p,sig_m_6p)))
A10: 8 | B10: =MAX(0,MIN(1,_xlfn.NORM.INV(RAND(),mu_m_13,sig_m_13))) | C10: =MAX(0,MIN(1,_xlfn.NORM.INV(RAND(),mu_m_13,sig_m_13))) | D10: =MAX(0,MIN(1,_xlfn.NORM.INV(RAND(),mu_m_13,sig_m_13))) | E10: =MAX(0,MIN(1,_xlfn.NORM.INV(RAND(),mu_m_45,sig_m_45))) | F10: =MAX(0,MIN(1,_xlfn.NORM.INV(RAND(),mu_m_45,sig_m_45))) | G10: =MAX(0,MIN(1,_xlfn.NORM.INV(RAND(),mu_m_6p,sig_m_6p))) | H10: =MAX(0,MIN(1,_xlfn.NORM.INV(RAND(),mu_m_6p,sig_m_6p))) | I10: =MAX(0,MIN(1,_xlfn.NORM.INV(RAND(),mu_m_6p,sig_m_6p))) | J10: =MAX(0,MIN(1,_xlfn.NORM.INV(RAND(),mu_m_6p,sig_m_6p))) | K10: =MAX(0,MIN(1,_xlfn.NORM.INV(RAND(),mu_m_6p,sig_m_6p)))
A11: 9 | B11: =MAX(0,MIN(1,_xlfn.NORM.INV(RAND(),mu_m_13,sig_m_13))) | C11: =MAX(0,MIN(1,_xlfn.NORM.INV(RAND(),mu_m_13,sig_m_13))) | D11: =MAX(0,MIN(1,_xlfn.NORM.INV(RAND(),mu_m_13,sig_m_13))) | E11: =MAX(0,MIN(1,_xlfn.NORM.INV(RAND(),mu_m_45,sig_m_45))) | F11: =MAX(0,MIN(1,_xlfn.NORM.INV(RAND(),mu_m_45,sig_m_45))) | G11: =MAX(0,MIN(1,_xlfn.NORM.INV(RAND(),mu_m_6p,sig_m_6p))) | H11: =MAX(0,MIN(1,_xlfn.NORM.INV(RAND(),mu_m_6p,sig_m_6p))) | I11: =MAX(0,MIN(1,_xlfn.NORM.INV(RAND(),mu_m_6p,sig_m_6p))) | J11: =MAX(0,MIN(1,_xlfn.NORM.INV(RAND(),mu_m_6p,sig_m_6p))) | K11: =MAX(0,MIN(1,_xlfn.NORM.INV(RAND(),mu_m_6p,sig_m_6p)))
A12: 10 | B12: =MAX(0,MIN(1,_xlfn.NORM.INV(RAND(),mu_m_13,sig_m_13))) | C12: =MAX(0,MIN(1,_xlfn.NORM.INV(RAND(),mu_m_13,sig_m_13))) | D12: =MAX(0,MIN(1,_xlfn.NORM.INV(RAND(),mu_m_13,sig_m_13))) | E12: =MAX(0,MIN(1,_xlfn.NORM.INV(RAND(),mu_m_45,sig_m_45))) | F12: =MAX(0,MIN(1,_xlfn.NORM.INV(RAND(),mu_m_45,sig_m_45))) | G12: =MAX(0,MIN(1,_xlfn.NORM.INV(RAND(),mu_m_6p,sig_m_6p))) | H12: =MAX(0,MIN(1,_xlfn.NORM.INV(RAND(),mu_m_6p,sig_m_6p))) | I12: =MAX(0,MIN(1,_xlfn.NORM.INV(RAND(),mu_m_6p,sig_m_6p))) | J12: =MAX(0,MIN(1,_xlfn.NORM.INV(RAND(),mu_m_6p,sig_m_6p))) | K12: =MAX(0,MIN(1,_xlfn.NORM.INV(RAND(),mu_m_6p,sig_m_6p)))
A13: 11 | B13: =MAX(0,MIN(1,_xlfn.NORM.INV(RAND(),mu_m_13,sig_m_13))) | C13: =MAX(0,MIN(1,_xlfn.NORM.INV(RAND(),mu_m_13,sig_m_13))) | D13: =MAX(0,MIN(1,_xlfn.NORM.INV(RAND(),mu_m_13,sig_m_13))) | E13: =MAX(0,MIN(1,_xlfn.NORM.INV(RAND(),mu_m_45,sig_m_45))) | F13: =MAX(0,MIN(1,_xlfn.NORM.INV(RAND(),mu_m_45,sig_m_45))) | G13: =MAX(0,MIN(1,_xlfn.NORM.INV(RAND(),mu_m_6p,sig_m_6p))) | H13: =MAX(0,MIN(1,_xlfn.NORM.INV(RAND(),mu_m_6p,sig_m_6p))) | I13: =MAX(0,MIN(1,_xlfn.NORM.INV(RAND(),mu_m_6p,sig_m_6p))) | J13: =MAX(0,MIN(1,_xlfn.NORM.INV(RAND(),mu_m_6p,sig_m_6p))) | K13: =MAX(0,MIN(1,_xlfn.NORM.INV(RAND(),mu_m_6p,sig_m_6p)))
... A32: 30 | B32: =MAX(0,MIN(1,_xlfn.NORM.INV(RAND(),mu_m_13,sig_m_13))) | C32: =MAX(0,MIN(1,_xlfn.NORM.INV(RAND(),mu_m_13,sig_m_13))) | D32: =MAX(0,MIN(1,_xlfn.NORM.INV(RAND(),mu_m_13,sig_m_13))) | E32: =MAX(0,MIN(1,_xlfn.NORM.INV(RAND(),mu_m_45,sig_m_45))) | F32: =MAX(0,MIN(1,_xlfn.NORM.INV(RAND(),mu_m_45,sig_m_45))) | G32: =MAX(0,MIN(1,_xlfn.NORM.INV(RAND(),mu_m_6p,sig_m_6p))) | H32: =MAX(0,MIN(1,_xlfn.NORM.INV(RAND(),mu_m_6p,sig_m_6p))) | I32: =MAX(0,MIN(1,_xlfn.NORM.INV(RAND(),mu_m_6p,sig_m_6p))) | J32: =MAX(0,MIN(1,_xlfn.NORM.INV(RAND(),mu_m_6p,sig_m_6p))) | K32: =MAX(0,MIN(1,_xlfn.NORM.INV(RAND(),mu_m_6p,sig_m_6p)))

Sheet pca
A1: t \ a | B1: a=1 | C1: a=2 | D1: a=3 | E1: a=4 | F1: a=5 | G1: a=6 | H1: a=7 | I1: a=8 | J1: a=9 | K1: a=10
A2: 0 | B2: 0 | C2: 0 | D2: 0 | E2: 0 | F2: 0 | G2: 0 | H2: 0 | I2: 0 | J2: 0 | K2: 0
A3: 1 | B3: =IFERROR(_xlfn.BINOM.INV(MAX(0,z!B2),MAX(0,MIN(1,pch!B2)),RAND()),0) | C3: =IFERROR(_xlfn.BINOM.INV(MAX(0,z!C2),MAX(0,MIN(1,pch!B2)),RAND()),0) | D3: =IFERROR(_xlfn.BINOM.INV(MAX(0,z!D2),MAX(0,MIN(1,pch!B2)),RAND()),0) | E3: =IFERROR(_xlfn.BINOM.INV(MAX(0,z!E2),MAX(0,MIN(1,pch!B2)),RAND()),0) | F3: =IFERROR(_xlfn.BINOM.INV(MAX(0,z!F2),MAX(0,MIN(1,pch!B2)),RAND()),0) | G3: =IFERROR(_xlfn.BINOM.INV(MAX(0,z!G2),MAX(0,MIN(1,pch!B2)),RAND()),0) | H3: =IFERROR(_xlfn.BINOM.INV(MAX(0,z!H2),MAX(0,MIN(1,pch!B2)),RAND()),0) | I3: =IFERROR(_xlfn.BINOM.INV(MAX(0,z!I2),MAX(0,MIN(1,pch!B2)),RAND()),0) | J3: =IFERROR(_xlfn.BINOM.INV(MAX(0,z!J2),MAX(0,MIN(1,pch!B2)),RAND()),0) | K3: =IFERROR(_xlfn.BINOM.INV(MAX(0,z!K2),MAX(0,MIN(1,pch!B2)),RAND()),0)
A4: 2 | B4: =IFERROR(_xlfn.BINOM.INV(MAX(0,z!B3),MAX(0,MIN(1,pch!B3)),RAND()),0) | C4: =IFERROR(_xlfn.BINOM.INV(MAX(0,z!C3),MAX(0,MIN(1,pch!B3)),RAND()),0) | D4: =IFERROR(_xlfn.BINOM.INV(MAX(0,z!D3),MAX(0,MIN(1,pch!B3)),RAND()),0) | E4: =IFERROR(_xlfn.BINOM.INV(MAX(0,z!E3),MAX(0,MIN(1,pch!B3)),RAND()),0) | F4: =IFERROR(_xlfn.BINOM.INV(MAX(0,z!F3),MAX(0,MIN(1,pch!B3)),RAND()),0) | G4: =IFERROR(_xlfn.BINOM.INV(MAX(0,z!G3),MAX(0,MIN(1,pch!B3)),RAND()),0) | H4: =IFERROR(_xlfn.BINOM.INV(MAX(0,z!H3),MAX(0,MIN(1,pch!B3)),RAND()),0) | I4: =IFERROR(_xlfn.BINOM.INV(MAX(0,z!I3),MAX(0,MIN(1,pch!B3)),RAND()),0) | J4: =IFERROR(_xlfn.BINOM.INV(MAX(0,z!J3),MAX(0,MIN(1,pch!B3)),RAND()),0) | K4: =IFERROR(_xlfn.BINOM.INV(MAX(0,z!K3),MAX(0,MIN(1,pch!B3)),RAND()),0)
A5: 3 | B5: =IFERROR(_xlfn.BINOM.INV(MAX(0,z!B4),MAX(0,MIN(1,pch!B4)),RAND()),0) | C5: =IFERROR(_xlfn.BINOM.INV(MAX(0,z!C4),MAX(0,MIN(1,pch!B4)),RAND()),0) | D5: =IFERROR(_xlfn.BINOM.INV(MAX(0,z!D4),MAX(0,MIN(1,pch!B4)),RAND()),0) | E5: =IFERROR(_xlfn.BINOM.INV(MAX(0,z!E4),MAX(0,MIN(1,pch!B4)),RAND()),0) | F5: =IFERROR(_xlfn.BINOM.INV(MAX(0,z!F4),MAX(0,MIN(1,pch!B4)),RAND()),0) | G5: =IFERROR(_xlfn.BINOM.INV(MAX(0,z!G4),MAX(0,MIN(1,pch!B4)),RAND()),0) | H5: =IFERROR(_xlfn.BINOM.INV(MAX(0,z!H4),MAX(0,MIN(1,pch!B4)),RAND()),0) | I5: =IFERROR(_xlfn.BINOM.INV(MAX(0,z!I4),MAX(0,MIN(1,pch!B4)),RAND()),0) | J5: =IFERROR(_xlfn.BINOM.INV(MAX(0,z!J4),MAX(0,MIN(1,pch!B4)),RAND()),0) | K5: =IFERROR(_xlfn.BINOM.INV(MAX(0,z!K4),MAX(0,MIN(1,pch!B4)),RAND()),0)
A6: 4 | B6: =IFERROR(_xlfn.BINOM.INV(MAX(0,z!B5),MAX(0,MIN(1,pch!B5)),RAND()),0) | C6: =IFERROR(_xlfn.BINOM.INV(MAX(0,z!C5),MAX(0,MIN(1,pch!B5)),RAND()),0) | D6: =IFERROR(_xlfn.BINOM.INV(MAX(0,z!D5),MAX(0,MIN(1,pch!B5)),RAND()),0) | E6: =IFERROR(_xlfn.BINOM.INV(MAX(0,z!E5),MAX(0,MIN(1,pch!B5)),RAND()),0) | F6: =IFERROR(_xlfn.BINOM.INV(MAX(0,z!F5),MAX(0,MIN(1,pch!B5)),RAND()),0) | G6: =IFERROR(_xlfn.BINOM.INV(MAX(0,z!G5),MAX(0,MIN(1,pch!B5)),RAND()),0) | H6: =IFERROR(_xlfn.BINOM.INV(MAX(0,z!H5),MAX(0,MIN(1,pch!B5)),RAND()),0) | I6: =IFERROR(_xlfn.BINOM.INV(MAX(0,z!I5),MAX(0,MIN(1,pch!B5)),RAND()),0) | J6: =IFERROR(_xlfn.BINOM.INV(MAX(0,z!J5),MAX(0,MIN(1,pch!B5)),RAND()),0) | K6: =IFERROR(_xlfn.BINOM.INV(MAX(0,z!K5),MAX(0,MIN(1,pch!B5)),RAND()),0)
A7: 5 | B7: =IFERROR(_xlfn.BINOM.INV(MAX(0,z!B6),MAX(0,MIN(1,pch!B6)),RAND()),0) | C7: =IFERROR(_xlfn.BINOM.INV(MAX(0,z!C6),MAX(0,MIN(1,pch!B6)),RAND()),0) | D7: =IFERROR(_xlfn.BINOM.INV(MAX(0,z!D6),MAX(0,MIN(1,pch!B6)),RAND()),0) | E7: =IFERROR(_xlfn.BINOM.INV(MAX(0,z!E6),MAX(0,MIN(1,pch!B6)),RAND()),0) | F7: =IFERROR(_xlfn.BINOM.INV(MAX(0,z!F6),MAX(0,MIN(1,pch!B6)),RAND()),0) | G7: =IFERROR(_xlfn.BINOM.INV(MAX(0,z!G6),MAX(0,MIN(1,pch!B6)),RAND()),0) | H7: =IFERROR(_xlfn.BINOM.INV(MAX(0,z!H6),MAX(0,MIN(1,pch!B6)),RAND()),0) | I7: =IFERROR(_xlfn.BINOM.INV(MAX(0,z!I6),MAX(0,MIN(1,pch!B6)),RAND()),0) | J7: =IFERROR(_xlfn.BINOM.INV(MAX(0,z!J6),MAX(0,MIN(1,pch!B6)),RAND()),0) | K7: =IFERROR(_xlfn.BINOM.INV(MAX(0,z!K6),MAX(0,MIN(1,pch!B6)),RAND()),0)
A8: 6 | B8: =IFERROR(_xlfn.BINOM.INV(MAX(0,z!B7),MAX(0,MIN(1,pch!B7)),RAND()),0) | C8: =IFERROR(_xlfn.BINOM.INV(MAX(0,z!C7),MAX(0,MIN(1,pch!B7)),RAND()),0) | D8: =IFERROR(_xlfn.BINOM.INV(MAX(0,z!D7),MAX(0,MIN(1,pch!B7)),RAND()),0) | E8: =IFERROR(_xlfn.BINOM.INV(MAX(0,z!E7),MAX(0,MIN(1,pch!B7)),RAND()),0) | F8: =IFERROR(_xlfn.BINOM.INV(MAX(0,z!F7),MAX(0,MIN(1,pch!B7)),RAND()),0) | G8: =IFERROR(_xlfn.BINOM.INV(MAX(0,z!G7),MAX(0,MIN(1,pch!B7)),RAND()),0) | H8: =IFERROR(_xlfn.BINOM.INV(MAX(0,z!H7),MAX(0,MIN(1,pch!B7)),RAND()),0) | I8: =IFERROR(_xlfn.BINOM.INV(MAX(0,z!I7),MAX(0,MIN(1,pch!B7)),RAND()),0) | J8: =IFERROR(_xlfn.BINOM.INV(MAX(0,z!J7),MAX(0,MIN(1,pch!B7)),RAND()),0) | K8: =IFERROR(_xlfn.BINOM.INV(MAX(0,z!K7),MAX(0,MIN(1,pch!B7)),RAND()),0)
A9: 7 | B9: =IFERROR(_xlfn.BINOM.INV(MAX(0,z!B8),MAX(0,MIN(1,pch!B8)),RAND()),0) | C9: =IFERROR(_xlfn.BINOM.INV(MAX(0,z!C8),MAX(0,MIN(1,pch!B8)),RAND()),0) | D9: =IFERROR(_xlfn.BINOM.INV(MAX(0,z!D8),MAX(0,MIN(1,pch!B8)),RAND()),0) | E9: =IFERROR(_xlfn.BINOM.INV(MAX(0,z!E8),MAX(0,MIN(1,pch!B8)),RAND()),0) | F9: =IFERROR(_xlfn.BINOM.INV(MAX(0,z!F8),MAX(0,MIN(1,pch!B8)),RAND()),0) | G9: =IFERROR(_xlfn.BINOM.INV(MAX(0,z!G8),MAX(0,MIN(1,pch!B8)),RAND()),0) | H9: =IFERROR(_xlfn.BINOM.INV(MAX(0,z!H8),MAX(0,MIN(1,pch!B8)),RAND()),0) | I9: =IFERROR(_xlfn.BINOM.INV(MAX(0,z!I8),MAX(0,MIN(1,pch!B8)),RAND()),0) | J9: =IFERROR(_xlfn.BINOM.INV(MAX(0,z!J8),MAX(0,MIN(1,pch!B8)),RAND()),0) | K9: =IFERROR(_xlfn.BINOM.INV(MAX(0,z!K8),MAX(0,MIN(1,pch!B8)),RAND()),0)
A10: 8 | B10: =IFERROR(_xlfn.BINOM.INV(MAX(0,z!B9),MAX(0,MIN(1,pch!B9)),RAND()),0) | C10: =IFERROR(_xlfn.BINOM.INV(MAX(0,z!C9),MAX(0,MIN(1,pch!B9)),RAND()),0) | D10: =IFERROR(_xlfn.BINOM.INV(MAX(0,z!D9),MAX(0,MIN(1,pch!B9)),RAND()),0) | E10: =IFERROR(_xlfn.BINOM.INV(MAX(0,z!E9),MAX(0,MIN(1,pch!B9)),RAND()),0) | F10: =IFERROR(_xlfn.BINOM.INV(MAX(0,z!F9),MAX(0,MIN(1,pch!B9)),RAND()),0) | G10: =IFERROR(_xlfn.BINOM.INV(MAX(0,z!G9),MAX(0,MIN(1,pch!B9)),RAND()),0) | H10: =IFERROR(_xlfn.BINOM.INV(MAX(0,z!H9),MAX(0,MIN(1,pch!B9)),RAND()),0) | I10: =IFERROR(_xlfn.BINOM.INV(MAX(0,z!I9),MAX(0,MIN(1,pch!B9)),RAND()),0) | J10: =IFERROR(_xlfn.BINOM.INV(MAX(0,z!J9),MAX(0,MIN(1,pch!B9)),RAND()),0) | K10: =IFERROR(_xlfn.BINOM.INV(MAX(0,z!K9),MAX(0,MIN(1,pch!B9)),RAND()),0)
A11: 9 | B11: =IFERROR(_xlfn.BINOM.INV(MAX(0,z!B10),MAX(0,MIN(1,pch!B10)),RAND()),0) | C11: =IFERROR(_xlfn.BINOM.INV(MAX(0,z!C10),MAX(0,MIN(1,pch!B10)),RAND()),0) | D11: =IFERROR(_xlfn.BINOM.INV(MAX(0,z!D10),MAX(0,MIN(1,pch!B10)),RAND()),0) | E11: =IFERROR(_xlfn.BINOM.INV(MAX(0,z!E10),MAX(0,MIN(1,pch!B10)),RAND()),0) | F11: =IFERROR(_xlfn.BINOM.INV(MAX(0,z!F10),MAX(0,MIN(1,pch!B10)),RAND()),0) | G11: =IFERROR(_xlfn.BINOM.INV(MAX(0,z!G10),MAX(0,MIN(1,pch!B10)),RAND()),0) | H11: =IFERROR(_xlfn.BINOM.INV(MAX(0,z!H10),MAX(0,MIN(1,pch!B10)),RAND()),0) | I11: =IFERROR(_xlfn.BINOM.INV(MAX(0,z!I10),MAX(0,MIN(1,pch!B10)),RAND()),0) | J11: =IFERROR(_xlfn.BINOM.INV(MAX(0,z!J10),MAX(0,MIN(1,pch!B10)),RAND()),0) | K11: =IFERROR(_xlfn.BINOM.INV(MAX(0,z!K10),MAX(0,MIN(1,pch!B10)),RAND()),0)
A12: 10 | B12: =IFERROR(_xlfn.BINOM.INV(MAX(0,z!B11),MAX(0,MIN(1,pch!B11)),RAND()),0) | C12: =IFERROR(_xlfn.BINOM.INV(MAX(0,z!C11),MAX(0,MIN(1,pch!B11)),RAND()),0) | D12: =IFERROR(_xlfn.BINOM.INV(MAX(0,z!D11),MAX(0,MIN(1,pch!B11)),RAND()),0) | E12: =IFERROR(_xlfn.BINOM.INV(MAX(0,z!E11),MAX(0,MIN(1,pch!B11)),RAND()),0) | F12: =IFERROR(_xlfn.BINOM.INV(MAX(0,z!F11),MAX(0,MIN(1,pch!B11)),RAND()),0) | G12: =IFERROR(_xlfn.BINOM.INV(MAX(0,z!G11),MAX(0,MIN(1,pch!B11)),RAND()),0) | H12: =IFERROR(_xlfn.BINOM.INV(MAX(0,z!H11),MAX(0,MIN(1,pch!B11)),RAND()),0) | I12: =IFERROR(_xlfn.BINOM.INV(MAX(0,z!I11),MAX(0,MIN(1,pch!B11)),RAND()),0) | J12: =IFERROR(_xlfn.BINOM.INV(MAX(0,z!J11),MAX(0,MIN(1,pch!B11)),RAND()),0) | K12: =IFERROR(_xlfn.BINOM.INV(MAX(0,z!K11),MAX(0,MIN(1,pch!B11)),RAND()),0)
A13: 11 | B13: =IFERROR(_xlfn.BINOM.INV(MAX(0,z!B12),MAX(0,MIN(1,pch!B12)),RAND()),0) | C13: =IFERROR(_xlfn.BINOM.INV(MAX(0,z!C12),MAX(0,MIN(1,pch!B12)),RAND()),0) | D13: =IFERROR(_xlfn.BINOM.INV(MAX(0,z!D12),MAX(0,MIN(1,pch!B12)),RAND()),0) | E13: =IFERROR(_xlfn.BINOM.INV(MAX(0,z!E12),MAX(0,MIN(1,pch!B12)),RAND()),0) | F13: =IFERROR(_xlfn.BINOM.INV(MAX(0,z!F12),MAX(0,MIN(1,pch!B12)),RAND()),0) | G13: =IFERROR(_xlfn.BINOM.INV(MAX(0,z!G12),MAX(0,MIN(1,pch!B12)),RAND()),0) | H13: =IFERROR(_xlfn.BINOM.INV(MAX(0,z!H12),MAX(0,MIN(1,pch!B12)),RAND()),0) | I13: =IFERROR(_xlfn.BINOM.INV(MAX(0,z!I12),MAX(0,MIN(1,pch!B12)),RAND()),0) | J13: =IFERROR(_xlfn.BINOM.INV(MAX(0,z!J12),MAX(0,MIN(1,pch!B12)),RAND()),0) | K13: =IFERROR(_xlfn.BINOM.INV(MAX(0,z!K12),MAX(0,MIN(1,pch!B12)),RAND()),0)
A14: 12 | B14: =IFERROR(_xlfn.BINOM.INV(MAX(0,z!B13),MAX(0,MIN(1,pch!B13)),RAND()),0) | C14: =IFERROR(_xlfn.BINOM.INV(MAX(0,z!C13),MAX(0,MIN(1,pch!B13)),RAND()),0) | D14: =IFERROR(_xlfn.BINOM.INV(MAX(0,z!D13),MAX(0,MIN(1,pch!B13)),RAND()),0) | E14: =IFERROR(_xlfn.BINOM.INV(MAX(0,z!E13),MAX(0,MIN(1,pch!B13)),RAND()),0) | F14: =IFERROR(_xlfn.BINOM.INV(MAX(0,z!F13),MAX(0,MIN(1,pch!B13)),RAND()),0) | G14: =IFERROR(_xlfn.BINOM.INV(MAX(0,z!G13),MAX(0,MIN(1,pch!B13)),RAND()),0) | H14: =IFERROR(_xlfn.BINOM.INV(MAX(0,z!H13),MAX(0,MIN(1,pch!B13)),RAND()),0) | I14: =IFERROR(_xlfn.BINOM.INV(MAX(0,z!I13),MAX(0,MIN(1,pch!B13)),RAND()),0) | J14: =IFERROR(_xlfn.BINOM.INV(MAX(0,z!J13),MAX(0,MIN(1,pch!B13)),RAND()),0) | K14: =IFERROR(_xlfn.BINOM.INV(MAX(0,z!K13),MAX(0,MIN(1,pch!B13)),RAND()),0)
... A32: 30 | B32: =IFERROR(_xlfn.BINOM.INV(MAX(0,z!B31),MAX(0,MIN(1,pch!B31)),RAND()),0) | C32: =IFERROR(_xlfn.BINOM.INV(MAX(0,z!C31),MAX(0,MIN(1,pch!B31)),RAND()),0) | D32: =IFERROR(_xlfn.BINOM.INV(MAX(0,z!D31),MAX(0,MIN(1,pch!B31)),RAND()),0) | E32: =IFERROR(_xlfn.BINOM.INV(MAX(0,z!E31),MAX(0,MIN(1,pch!B31)),RAND()),0) | F32: =IFERROR(_xlfn.BINOM.INV(MAX(0,z!F31),MAX(0,MIN(1,pch!B31)),RAND()),0) | G32: =IFERROR(_xlfn.BINOM.INV(MAX(0,z!G31),MAX(0,MIN(1,pch!B31)),RAND()),0) | H32: =IFERROR(_xlfn.BINOM.INV(MAX(0,z!H31),MAX(0,MIN(1,pch!B31)),RAND()),0) | I32: =IFERROR(_xlfn.BINOM.INV(MAX(0,z!I31),MAX(0,MIN(1,pch!B31)),RAND()),0) | J32: =IFERROR(_xlfn.BINOM.INV(MAX(0,z!J31),MAX(0,MIN(1,pch!B31)),RAND()),0) | K32: =IFERROR(_xlfn.BINOM.INV(MAX(0,z!K31),MAX(0,MIN(1,pch!B31)),RAND()),0)

Sheet pu
A1: t \ a | B1: a=1 | C1: a=2 | D1: a=3 | E1: a=4 | F1: a=5 | G1: a=6 | H1: a=7 | I1: a=8 | J1: a=9 | K1: a=10
A2: 0 | B2: 0 | C2: 0 | D2: 0 | E2: 0 | F2: 0 | G2: 0 | H2: 0 | I2: 0 | J2: 0 | K2: 0
A3: 1 | B3: =IFERROR(_xlfn.BINOM.INV(MAX(0,cb!B2),MAX(0,MIN(1,m_st!B3)),RAND()),0) | C3: =IFERROR(_xlfn.BINOM.INV(MAX(0,cb!C2),MAX(0,MIN(1,m_st!C3)),RAND()),0) | D3: =IFERROR(_xlfn.BINOM.INV(MAX(0,cb!D2),MAX(0,MIN(1,m_st!D3)),RAND()),0) | E3: =IFERROR(_xlfn.BINOM.INV(MAX(0,cb!E2),MAX(0,MIN(1,m_st!E3)),RAND()),0) | F3: =IFERROR(_xlfn.BINOM.INV(MAX(0,cb!F2),MAX(0,MIN(1,m_st!F3)),RAND()),0) | G3: =IFERROR(_xlfn.BINOM.INV(MAX(0,cb!G2),MAX(0,MIN(1,m_st!G3)),RAND()),0) | H3: =IFERROR(_xlfn.BINOM.INV(MAX(0,cb!H2),MAX(0,MIN(1,m_st!H3)),RAND()),0) | I3: =IFERROR(_xlfn.BINOM.INV(MAX(0,cb!I2),MAX(0,MIN(1,m_st!I3)),RAND()),0) | ... K3: =IFERROR(_xlfn.BINOM.INV(MAX(0,cb!K2),MAX(0,MIN(1,m_st!K3)),RAND()),0)
A4: 2 | B4: =IFERROR(_xlfn.BINOM.INV(MAX(0,cb!B3),MAX(0,MIN(1,m_st!B4)),RAND()),0) | C4: =IFERROR(_xlfn.BINOM.INV(MAX(0,cb!C3),MAX(0,MIN(1,m_st!C4)),RAND()),0) | D4: =IFERROR(_xlfn.BINOM.INV(MAX(0,cb!D3),MAX(0,MIN(1,m_st!D4)),RAND()),0) | E4: =IFERROR(_xlfn.BINOM.INV(MAX(0,cb!E3),MAX(0,MIN(1,m_st!E4)),RAND()),0) | F4: =IFERROR(_xlfn.BINOM.INV(MAX(0,cb!F3),MAX(0,MIN(1,m_st!F4)),RAND()),0) | G4: =IFERROR(_xlfn.BINOM.INV(MAX(0,cb!G3),MAX(0,MIN(1,m_st!G4)),RAND()),0) | H4: =IFERROR(_xlfn.BINOM.INV(MAX(0,cb!H3),MAX(0,MIN(1,m_st!H4)),RAND()),0) | I4: =IFERROR(_xlfn.BINOM.INV(MAX(0,cb!I3),MAX(0,MIN(1,m_st!I4)),RAND()),0) | ... K4: =IFERROR(_xlfn.BINOM.INV(MAX(0,cb!K3),MAX(0,MIN(1,m_st!K4)),RAND()),0)
A5: 3 | B5: =IFERROR(_xlfn.BINOM.INV(MAX(0,cb!B4),MAX(0,MIN(1,m_st!B5)),RAND()),0) | C5: =IFERROR(_xlfn.BINOM.INV(MAX(0,cb!C4),MAX(0,MIN(1,m_st!C5)),RAND()),0) | D5: =IFERROR(_xlfn.BINOM.INV(MAX(0,cb!D4),MAX(0,MIN(1,m_st!D5)),RAND()),0) | E5: =IFERROR(_xlfn.BINOM.INV(MAX(0,cb!E4),MAX(0,MIN(1,m_st!E5)),RAND()),0) | F5: =IFERROR(_xlfn.BINOM.INV(MAX(0,cb!F4),MAX(0,MIN(1,m_st!F5)),RAND()),0) | G5: =IFERROR(_xlfn.BINOM.INV(MAX(0,cb!G4),MAX(0,MIN(1,m_st!G5)),RAND()),0) | H5: =IFERROR(_xlfn.BINOM.INV(MAX(0,cb!H4),MAX(0,MIN(1,m_st!H5)),RAND()),0) | I5: =IFERROR(_xlfn.BINOM.INV(MAX(0,cb!I4),MAX(0,MIN(1,m_st!I5)),RAND()),0) | ... K5: =IFERROR(_xlfn.BINOM.INV(MAX(0,cb!K4),MAX(0,MIN(1,m_st!K5)),RAND()),0)
A6: 4 | B6: =IFERROR(_xlfn.BINOM.INV(MAX(0,cb!B5),MAX(0,MIN(1,m_st!B6)),RAND()),0) | C6: =IFERROR(_xlfn.BINOM.INV(MAX(0,cb!C5),MAX(0,MIN(1,m_st!C6)),RAND()),0) | D6: =IFERROR(_xlfn.BINOM.INV(MAX(0,cb!D5),MAX(0,MIN(1,m_st!D6)),RAND()),0) | E6: =IFERROR(_xlfn.BINOM.INV(MAX(0,cb!E5),MAX(0,MIN(1,m_st!E6)),RAND()),0) | F6: =IFERROR(_xlfn.BINOM.INV(MAX(0,cb!F5),MAX(0,MIN(1,m_st!F6)),RAND()),0) | G6: =IFERROR(_xlfn.BINOM.INV(MAX(0,cb!G5),MAX(0,MIN(1,m_st!G6)),RAND()),0) | H6: =IFERROR(_xlfn.BINOM.INV(MAX(0,cb!H5),MAX(0,MIN(1,m_st!H6)),RAND()),0) | I6: =IFERROR(_xlfn.BINOM.INV(MAX(0,cb!I5),MAX(0,MIN(1,m_st!I6)),RAND()),0) | ... K6: =IFERROR(_xlfn.BINOM.INV(MAX(0,cb!K5),MAX(0,MIN(1,m_st!K6)),RAND()),0)
A7: 5 | B7: =IFERROR(_xlfn.BINOM.INV(MAX(0,cb!B6),MAX(0,MIN(1,m_st!B7)),RAND()),0) | C7: =IFERROR(_xlfn.BINOM.INV(MAX(0,cb!C6),MAX(0,MIN(1,m_st!C7)),RAND()),0) | D7: =IFERROR(_xlfn.BINOM.INV(MAX(0,cb!D6),MAX(0,MIN(1,m_st!D7)),RAND()),0) | E7: =IFERROR(_xlfn.BINOM.INV(MAX(0,cb!E6),MAX(0,MIN(1,m_st!E7)),RAND()),0) | F7: =IFERROR(_xlfn.BINOM.INV(MAX(0,cb!F6),MAX(0,MIN(1,m_st!F7)),RAND()),0) | G7: =IFERROR(_xlfn.BINOM.INV(MAX(0,cb!G6),MAX(0,MIN(1,m_st!G7)),RAND()),0) | H7: =IFERROR(_xlfn.BINOM.INV(MAX(0,cb!H6),MAX(0,MIN(1,m_st!H7)),RAND()),0) | I7: =IFERROR(_xlfn.BINOM.INV(MAX(0,cb!I6),MAX(0,MIN(1,m_st!I7)),RAND()),0) | ... K7: =IFERROR(_xlfn.BINOM.INV(MAX(0,cb!K6),MAX(0,MIN(1,m_st!K7)),RAND()),0)
A8: 6 | B8: =IFERROR(_xlfn.BINOM.INV(MAX(0,cb!B7),MAX(0,MIN(1,m_st!B8)),RAND()),0) | C8: =IFERROR(_xlfn.BINOM.INV(MAX(0,cb!C7),MAX(0,MIN(1,m_st!C8)),RAND()),0) | D8: =IFERROR(_xlfn.BINOM.INV(MAX(0,cb!D7),MAX(0,MIN(1,m_st!D8)),RAND()),0) | E8: =IFERROR(_xlfn.BINOM.INV(MAX(0,cb!E7),MAX(0,MIN(1,m_st!E8)),RAND()),0) | F8: =IFERROR(_xlfn.BINOM.INV(MAX(0,cb!F7),MAX(0,MIN(1,m_st!F8)),RAND()),0) | G8: =IFERROR(_xlfn.BINOM.INV(MAX(0,cb!G7),MAX(0,MIN(1,m_st!G8)),RAND()),0) | H8: =IFERROR(_xlfn.BINOM.INV(MAX(0,cb!H7),MAX(0,MIN(1,m_st!H8)),RAND()),0) | I8: =IFERROR(_xlfn.BINOM.INV(MAX(0,cb!I7),MAX(0,MIN(1,m_st!I8)),RAND()),0) | ... K8: =IFERROR(_xlfn.BINOM.INV(MAX(0,cb!K7),MAX(0,MIN(1,m_st!K8)),RAND()),0)
A9: 7 | B9: =IFERROR(_xlfn.BINOM.INV(MAX(0,cb!B8),MAX(0,MIN(1,m_st!B9)),RAND()),0) | C9: =IFERROR(_xlfn.BINOM.INV(MAX(0,cb!C8),MAX(0,MIN(1,m_st!C9)),RAND()),0) | D9: =IFERROR(_xlfn.BINOM.INV(MAX(0,cb!D8),MAX(0,MIN(1,m_st!D9)),RAND()),0) | E9: =IFERROR(_xlfn.BINOM.INV(MAX(0,cb!E8),MAX(0,MIN(1,m_st!E9)),RAND()),0) | F9: =IFERROR(_xlfn.BINOM.INV(MAX(0,cb!F8),MAX(0,MIN(1,m_st!F9)),RAND()),0) | G9: =IFERROR(_xlfn.BINOM.INV(MAX(0,cb!G8),MAX(0,MIN(1,m_st!G9)),RAND()),0) | H9: =IFERROR(_xlfn.BINOM.INV(MAX(0,cb!H8),MAX(0,MIN(1,m_st!H9)),RAND()),0) | I9: =IFERROR(_xlfn.BINOM.INV(MAX(0,cb!I8),MAX(0,MIN(1,m_st!I9)),RAND()),0) | ... K9: =IFERROR(_xlfn.BINOM.INV(MAX(0,cb!K8),MAX(0,MIN(1,m_st!K9)),RAND()),0)
A10: 8 | B10: =IFERROR(_xlfn.BINOM.INV(MAX(0,cb!B9),MAX(0,MIN(1,m_st!B10)),RAND()),0) | C10: =IFERROR(_xlfn.BINOM.INV(MAX(0,cb!C9),MAX(0,MIN(1,m_st!C10)),RAND()),0) | D10: =IFERROR(_xlfn.BINOM.INV(MAX(0,cb!D9),MAX(0,MIN(1,m_st!D10)),RAND()),0) | E10: =IFERROR(_xlfn.BINOM.INV(MAX(0,cb!E9),MAX(0,MIN(1,m_st!E10)),RAND()),0) | F10: =IFERROR(_xlfn.BINOM.INV(MAX(0,cb!F9),MAX(0,MIN(1,m_st!F10)),RAND()),0) | G10: =IFERROR(_xlfn.BINOM.INV(MAX(0,cb!G9),MAX(0,MIN(1,m_st!G10)),RAND()),0) | H10: =IFERROR(_xlfn.BINOM.INV(MAX(0,cb!H9),MAX(0,MIN(1,m_st!H10)),RAND()),0) | I10: =IFERROR(_xlfn.BINOM.INV(MAX(0,cb!I9),MAX(0,MIN(1,m_st!I10)),RAND()),0) | ... K10: =IFERROR(_xlfn.BINOM.INV(MAX(0,cb!K9),MAX(0,MIN(1,m_st!K10)),RAND()),0)
A11: 9 | B11: =IFERROR(_xlfn.BINOM.INV(MAX(0,cb!B10),MAX(0,MIN(1,m_st!B11)),RAND()),0) | C11: =IFERROR(_xlfn.BINOM.INV(MAX(0,cb!C10),MAX(0,MIN(1,m_st!C11)),RAND()),0) | D11: =IFERROR(_xlfn.BINOM.INV(MAX(0,cb!D10),MAX(0,MIN(1,m_st!D11)),RAND()),0) | E11: =IFERROR(_xlfn.BINOM.INV(MAX(0,cb!E10),MAX(0,MIN(1,m_st!E11)),RAND()),0) | F11: =IFERROR(_xlfn.BINOM.INV(MAX(0,cb!F10),MAX(0,MIN(1,m_st!F11)),RAND()),0) | G11: =IFERROR(_xlfn.BINOM.INV(MAX(0,cb!G10),MAX(0,MIN(1,m_st!G11)),RAND()),0) | H11: =IFERROR(_xlfn.BINOM.INV(MAX(0,cb!H10),MAX(0,MIN(1,m_st!H11)),RAND()),0) | I11: =IFERROR(_xlfn.BINOM.INV(MAX(0,cb!I10),MAX(0,MIN(1,m_st!I11)),RAND()),0) | ... K11: =IFERROR(_xlfn.BINOM.INV(MAX(0,cb!K10),MAX(0,MIN(1,m_st!K11)),RAND()),0)
A12: 10 | B12: =IFERROR(_xlfn.BINOM.INV(MAX(0,cb!B11),MAX(0,MIN(1,m_st!B12)),RAND()),0) | C12: =IFERROR(_xlfn.BINOM.INV(MAX(0,cb!C11),MAX(0,MIN(1,m_st!C12)),RAND()),0) | D12: =IFERROR(_xlfn.BINOM.INV(MAX(0,cb!D11),MAX(0,MIN(1,m_st!D12)),RAND()),0) | E12: =IFERROR(_xlfn.BINOM.INV(MAX(0,cb!E11),MAX(0,MIN(1,m_st!E12)),RAND()),0) | F12: =IFERROR(_xlfn.BINOM.INV(MAX(0,cb!F11),MAX(0,MIN(1,m_st!F12)),RAND()),0) | G12: =IFERROR(_xlfn.BINOM.INV(MAX(0,cb!G11),MAX(0,MIN(1,m_st!G12)),RAND()),0) | H12: =IFERROR(_xlfn.BINOM.INV(MAX(0,cb!H11),MAX(0,MIN(1,m_st!H12)),RAND()),0) | I12: =IFERROR(_xlfn.BINOM.INV(MAX(0,cb!I11),MAX(0,MIN(1,m_st!I12)),RAND()),0) | ... K12: =IFERROR(_xlfn.BINOM.INV(MAX(0,cb!K11),MAX(0,MIN(1,m_st!K12)),RAND()),0)
A13: 11 | B13: =IFERROR(_xlfn.BINOM.INV(MAX(0,cb!B12),MAX(0,MIN(1,m_st!B13)),RAND()),0) | C13: =IFERROR(_xlfn.BINOM.INV(MAX(0,cb!C12),MAX(0,MIN(1,m_st!C13)),RAND()),0) | D13: =IFERROR(_xlfn.BINOM.INV(MAX(0,cb!D12),MAX(0,MIN(1,m_st!D13)),RAND()),0) | E13: =IFERROR(_xlfn.BINOM.INV(MAX(0,cb!E12),MAX(0,MIN(1,m_st!E13)),RAND()),0) | F13: =IFERROR(_xlfn.BINOM.INV(MAX(0,cb!F12),MAX(0,MIN(1,m_st!F13)),RAND()),0) | G13: =IFERROR(_xlfn.BINOM.INV(MAX(0,cb!G12),MAX(0,MIN(1,m_st!G13)),RAND()),0) | H13: =IFERROR(_xlfn.BINOM.INV(MAX(0,cb!H12),MAX(0,MIN(1,m_st!H13)),RAND()),0) | I13: =IFERROR(_xlfn.BINOM.INV(MAX(0,cb!I12),MAX(0,MIN(1,m_st!I13)),RAND()),0) | ... K13: =IFERROR(_xlfn.BINOM.INV(MAX(0,cb!K12),MAX(0,MIN(1,m_st!K13)),RAND()),0)
A14: 12 | B14: =IFERROR(_xlfn.BINOM.INV(MAX(0,cb!B13),MAX(0,MIN(1,m_st!B14)),RAND()),0) | C14: =IFERROR(_xlfn.BINOM.INV(MAX(0,cb!C13),MAX(0,MIN(1,m_st!C14)),RAND()),0) | D14: =IFERROR(_xlfn.BINOM.INV(MAX(0,cb!D13),MAX(0,MIN(1,m_st!D14)),RAND()),0) | E14: =IFERROR(_xlfn.BINOM.INV(MAX(0,cb!E13),MAX(0,MIN(1,m_st!E14)),RAND()),0) | F14: =IFERROR(_xlfn.BINOM.INV(MAX(0,cb!F13),MAX(0,MIN(1,m_st!F14)),RAND()),0) | G14: =IFERROR(_xlfn.BINOM.INV(MAX(0,cb!G13),MAX(0,MIN(1,m_st!G14)),RAND()),0) | H14: =IFERROR(_xlfn.BINOM.INV(MAX(0,cb!H13),MAX(0,MIN(1,m_st!H14)),RAND()),0) | I14: =IFERROR(_xlfn.BINOM.INV(MAX(0,cb!I13),MAX(0,MIN(1,m_st!I14)),RAND()),0) | ... K14: =IFERROR(_xlfn.BINOM.INV(MAX(0,cb!K13),MAX(0,MIN(1,m_st!K14)),RAND()),0)
